Workbook

Sheet Tabellone
B2: LEGA ULTIMATE SCLERO VERGOGNA - BILIARDO - STAGIONE 1 (26/27) | M2: Legenda livello | R2: Storico coppie | Z2: CLASSIFICA ELO | AG2: CLASSIFICA LIVE - TOP 10 GIOCATORI | AM2: CLASSIFICA LIVE - TOP 10 COPPIE
B3: Giocatore | D3: Partite | E3: Vittorie | F3: % Vittoria | G3: Streak attiva | H3: Peggiore streak | I3: Migliore streak | J3: Punti Elo | K3: Perfect | M3: 1 - Senza mani | N3: Fatica a colpire la palla dritta, commette falli continui e segna solo per puro caso. | R3: Coppia | T3: Partite | U3: Vittorie | V3: % Vittorie | W3: Migliore streak | X3: Peggiore streak | Z3: Posizione | AA3: Giocatore | AB3: Elo Attuale | AC3: Partite | AD3: Vinte | AE3: Perse | AG3: Posizione | AH3: Giocatore | AI3: Vittorie | AJ3: % Vittorie | AK3: Indice di forza | AM3: Posizione | AN3: Coppia | AO3: Vittorie | AP3: % Vittorie | AQ3: Indice di forza
B4: Francia | D4: 30 | E4: 19 | F4: =IFERROR(ROUND(E4/D4, 3)*100 & "%", "N/A") -> 63,3% | G4: 2 | H4: -3 | I4: 7 | K4: 0 | R4: Francia + Matos | T4: 9 | U4: 7 | V4: =ROUND(U4/T4, 3)*100 & "%" -> 77,8% | W4: 7 | X4: -1 | Z4: 1 | AA4: {=Classifica!B2:B14} -> Francia | AB4: {=ROUND(Classifica!C2:C14,0)} -> 616 | AC4: {=Classifica!D2:F14} -> 30 | AD4: 19 | AE4: 11 | AG4: 1 | AH4: =IFERROR(__xludf.DUMMYFUNCTION("LET(g, FILTER(B4:B29, B4:B29<>""""), p, FILTER(D4:D29, B4:B29<>""""), v, FILTER(E4:E29, B4:B29<>""""), pct, FILTER(F4:F29, B4:B29<>""""), score, ARRAYFORMULA(v*(v/p)), ARRAY_CONSTRAIN(SORT(HSTACK(g, v, pct, ROUND(score, 2)), 4, FALSE, 2, FALSE), 10, 4))"),"Matos") -> Matos | AI4: =IFERROR(__xludf.DUMMYFUNCTION("""COMPUTED_VALUE"""),25.0) -> 25 | AJ4: =IFERROR(__xludf.DUMMYFUNCTION("""COMPUTED_VALUE"""),"55,6%") -> 55,6% | AK4: =IFERROR(__xludf.DUMMYFUNCTION("""COMPUTED_VALUE"""),13.89) -> 13.89 | AM4: 1 | AN4: =IFERROR(__xludf.DUMMYFUNCTION("LET(c, FILTER(R4:R50, R4:R50<>""""), p, FILTER(T4:T50, R4:R50<>""""), v, FILTER(U4:U50, R4:R50<>""""), pct, FILTER(V4:V50, R4:R50<>""""), score, ARRAYFORMULA(v*(v/p)), ARRAY_CONSTRAIN(SORT(HSTACK(c, v, pct, ROUND (score, 2)), 4, FALSE, 2, FALSE), 10, 4))"),"Francia + Matos") -> Francia + Matos | AO4: =IFERROR(__xludf.DUMMYFUNCTION("""COMPUTED_VALUE"""),7.0) -> 7 | AP4: =IFERROR(__xludf.DUMMYFUNCTION("""COMPUTED_VALUE"""),"77,8%") -> 77,8% | AQ4: =IFERROR(__xludf.DUMMYFUNCTION("""COMPUTED_VALUE"""),5.44) -> 5.44
M5: 2 - Base | N5: Imbuca tiri facili e diretti, ma ignora la forza del colpo e dove andrà a finire la bianca. | R5: Bonny + Gae | T5: 9 | U5: 2 | V5: =ROUND(U5/T5, 3)*100 & "%" -> 22,2% | W5: 1 | X5: -7 | Z5: 2 | AA5: Matos | AB5: 608 | AC5: 45 | AD5: 25 | AE5: 20 | AG5: 2 | AH5: =IFERROR(__xludf.DUMMYFUNCTION("""COMPUTED_VALUE"""),"Francia") -> Francia | AI5: =IFERROR(__xludf.DUMMYFUNCTION("""COMPUTED_VALUE"""),19.0) -> 19 | AJ5: =IFERROR(__xludf.DUMMYFUNCTION("""COMPUTED_VALUE"""),"63,3%") -> 63,3% | AK5: =IFERROR(__xludf.DUMMYFUNCTION("""COMPUTED_VALUE"""),12.03) -> 12.03 | AM5: 2 | AN5: =IFERROR(__xludf.DUMMYFUNCTION("""COMPUTED_VALUE"""),"Francia + Gae") -> Francia + Gae | AO5: =IFERROR(__xludf.DUMMYFUNCTION("""COMPUTED_VALUE"""),5.0) -> 5 | AP5: =IFERROR(__xludf.DUMMYFUNCTION("""COMPUTED_VALUE"""),"83,3%") -> 83,3% | AQ5: =IFERROR(__xludf.DUMMYFUNCTION("""COMPUTED_VALUE"""),4.17) -> 4.17
B6: Matos | D6: 45 | E6: 25 | F6: =IFERROR(ROUND(E6/D6, 3)*100 & "%" , "N/A") -> 55,6% | G6: -2 | H6: -3 | I6: 7 | K6: 0 | R6: Birra + Gae | T6: 7 | U6: 4 | V6: =ROUND(U6/T6, 3)*100 & "%" -> 57,1% | W6: 4 | X6: -3 | Z6: 3 | AA6: Vesco | AB6: 591 | AC6: 21 | AD6: 12 | AE6: 9 | AG6: 3 | AH6: =IFERROR(__xludf.DUMMYFUNCTION("""COMPUTED_VALUE"""),"Gae") -> Gae | AI6: =IFERROR(__xludf.DUMMYFUNCTION("""COMPUTED_VALUE"""),24.0) -> 24 | AJ6: =IFERROR(__xludf.DUMMYFUNCTION("""COMPUTED_VALUE"""),"50%") -> 50% | AK6: =IFERROR(__xludf.DUMMYFUNCTION("""COMPUTED_VALUE"""),12.0) -> 12 | AM6: 3 | AN6: =IFERROR(__xludf.DUMMYFUNCTION("""COMPUTED_VALUE"""),"Vesco + Matos") -> Vesco + Matos | AO6: =IFERROR(__xludf.DUMMYFUNCTION("""COMPUTED_VALUE"""),5.0) -> 5 | AP6: =IFERROR(__xludf.DUMMYFUNCTION("""COMPUTED_VALUE"""),"83,3%") -> 83,3% | AQ6: =IFERROR(__xludf.DUMMYFUNCTION("""COMPUTED_VALUE"""),4.17) -> 4.17
M7: 3 - Intermedio | N7: Buona mira di base, fa scelte strategiche e comincia a posizionarsi per il tiro successivo. | R7: Ricky + Col | T7: 7 | U7: 4 | V7: =ROUND(U7/T7, 3)*100 & "%" -> 57,1% | W7: 2 | X7: -2 | Z7: 4 | AA7: Paolo | AB7: 582 | AC7: 45 | AD7: 22 | AE7: 23 | AG7: 4 | AH7: =IFERROR(__xludf.DUMMYFUNCTION("""COMPUTED_VALUE"""),"Paolo") -> Paolo | AI7: =IFERROR(__xludf.DUMMYFUNCTION("""COMPUTED_VALUE"""),19.0) -> 19 | AJ7: =IFERROR(__xludf.DUMMYFUNCTION("""COMPUTED_VALUE"""),"47,5%") -> 47,5% | AK7: =IFERROR(__xludf.DUMMYFUNCTION("""COMPUTED_VALUE"""),9.03) -> 9.03 | AM7: 4 | AN7: =IFERROR(__xludf.DUMMYFUNCTION("""COMPUTED_VALUE"""),"Gae + Filli") -> Gae + Filli | AO7: =IFERROR(__xludf.DUMMYFUNCTION("""COMPUTED_VALUE"""),5.0) -> 5 | AP7: =IFERROR(__xludf.DUMMYFUNCTION("""COMPUTED_VALUE"""),"62,5%") -> 62,5% | AQ7: =IFERROR(__xludf.DUMMYFUNCTION("""COMPUTED_VALUE"""),3.13) -> 3.13
B8: Gae | D8: 48 | E8: 24 | F8: =IFERROR(ROUND(E8/D8, 3)*100 & "%" , "N/A") -> 50% | G8: 2 | H8: -7 | I8: 9 | K8: 0 | R8: Matos + Filli | T8: 7 | U8: 3 | V8: =ROUND(U8/T8, 3)*100 & "%" -> 42,9% | W8: 2 | X8: -3 | Z8: 5 | AA8: Birra | AB8: 563 | AC8: 7 | AD8: 4 | AE8: 3 | AG8: 5 | AH8: =IFERROR(__xludf.DUMMYFUNCTION("""COMPUTED_VALUE"""),"Filli") -> Filli | AI8: =IFERROR(__xludf.DUMMYFUNCTION("""COMPUTED_VALUE"""),15.0) -> 15 | AJ8: =IFERROR(__xludf.DUMMYFUNCTION("""COMPUTED_VALUE"""),"53,6%") -> 53,6% | AK8: =IFERROR(__xludf.DUMMYFUNCTION("""COMPUTED_VALUE"""),8.04) -> 8.04 | AM8: 5 | AN8: =IFERROR(__xludf.DUMMYFUNCTION("""COMPUTED_VALUE"""),"Birra + Gae") -> Birra + Gae | AO8: =IFERROR(__xludf.DUMMYFUNCTION("""COMPUTED_VALUE"""),4.0) -> 4 | AP8: =IFERROR(__xludf.DUMMYFUNCTION("""COMPUTED_VALUE"""),"57,1%") -> 57,1% | AQ8: =IFERROR(__xludf.DUMMYFUNCTION("""COMPUTED_VALUE"""),2.29) -> 2.29
M9: 4 - Avanzato | N9: Capace di usare le sponde, gioca di tattica e pianifica la serie con 2-3 tiri d'anticipo. | R9: Paolo + Francia | T9: 7 | U9: 3 | V9: =ROUND(U9/T9, 3)*100 & "%" -> 42,9% | W9: 2 | X9: -3 | Z9: 6 | AA9: Gae | AB9: 534 | AC9: 50 | AD9: 24 | AE9: 26 | AG9: 6 | AH9: =IFERROR(__xludf.DUMMYFUNCTION("""COMPUTED_VALUE"""),"Vesco") -> Vesco | AI9: =IFERROR(__xludf.DUMMYFUNCTION("""COMPUTED_VALUE"""),12.0) -> 12 | AJ9: =IFERROR(__xludf.DUMMYFUNCTION("""COMPUTED_VALUE"""),"57,1%") -> 57,1% | AK9: =IFERROR(__xludf.DUMMYFUNCTION("""COMPUTED_VALUE"""),6.86) -> 6.86 | AM9: 6 | AN9: =IFERROR(__xludf.DUMMYFUNCTION("""COMPUTED_VALUE"""),"Ricky + Col") -> Ricky + Col | AO9: =IFERROR(__xludf.DUMMYFUNCTION("""COMPUTED_VALUE"""),4.0) -> 4 | AP9: =IFERROR(__xludf.DUMMYFUNCTION("""COMPUTED_VALUE"""),"57,1%") -> 57,1% | AQ9: =IFERROR(__xludf.DUMMYFUNCTION("""COMPUTED_VALUE"""),2.29) -> 2.29
B10: Bonny | D10: 41 | E10: 15 | F10: =IFERROR(ROUND(E10/D10, 3)*100 & "%" , "N/A") -> 36,6% | G10: -2 | H10: -7 | I10: 3 | K10: 0 | R10: Francia + Gae | T10: 6 | U10: 5 | V10: =ROUND(U10/T10, 3)*100 & "%" -> 83,3% | W10: 5 | X10: -1 | Z10: 7 | AA10: Filli | AB10: 528 | AC10: 29 | AD10: 16 | AE10: 13 | AG10: 7 | AH10: =IFERROR(__xludf.DUMMYFUNCTION("""COMPUTED_VALUE"""),"Bonny") -> Bonny | AI10: =IFERROR(__xludf.DUMMYFUNCTION("""COMPUTED_VALUE"""),15.0) -> 15 | AJ10: =IFERROR(__xludf.DUMMYFUNCTION("""COMPUTED_VALUE"""),"36,6%") -> 36,6% | AK10: =IFERROR(__xludf.DUMMYFUNCTION("""COMPUTED_VALUE"""),5.49) -> 5.49 | AM10: 7 | AN10: =IFERROR(__xludf.DUMMYFUNCTION("""COMPUTED_VALUE"""),"Matos + Gae") -> Matos + Gae | AO10: =IFERROR(__xludf.DUMMYFUNCTION("""COMPUTED_VALUE"""),4.0) -> 4 | AP10: =IFERROR(__xludf.DUMMYFUNCTION("""COMPUTED_VALUE"""),"57,1%") -> 57,1% | AQ10: =IFERROR(__xludf.DUMMYFUNCTION("""COMPUTED_VALUE"""),2.29) -> 2.29
M11: 5 - Fuoriclasse | N11: Controllo millimetrico dello spin e delle traiettorie complesse; può ripulire il tavolo in un unico turno. | R11: Vesco + Picci | T11: 6 | U11: 3 | V11: =ROUND(U11/T11, 3)*100 & "%" -> 50% | W11: 2 | X11: -1 | Z11: 8 | AA11: Col | AB11: 525 | AC11: 7 | AD11: 4 | AE11: 3 | AG11: 8 | AH11: =IFERROR(__xludf.DUMMYFUNCTION("""COMPUTED_VALUE"""),"Ricky") -> Ricky | AI11: =IFERROR(__xludf.DUMMYFUNCTION("""COMPUTED_VALUE"""),11.0) -> 11 | AJ11: =IFERROR(__xludf.DUMMYFUNCTION("""COMPUTED_VALUE"""),"45,8%") -> 45,8% | AK11: =IFERROR(__xludf.DUMMYFUNCTION("""COMPUTED_VALUE"""),5.04) -> 5.04 | AM11: 8 | AN11: =IFERROR(__xludf.DUMMYFUNCTION("""COMPUTED_VALUE"""),"Gae + Paolo") -> Gae + Paolo | AO11: =IFERROR(__xludf.DUMMYFUNCTION("""COMPUTED_VALUE"""),3.0) -> 3 | AP11: =IFERROR(__xludf.DUMMYFUNCTION("""COMPUTED_VALUE"""),"60%") -> 60% | AQ11: =IFERROR(__xludf.DUMMYFUNCTION("""COMPUTED_VALUE"""),1.8) -> 1.8
B12: Ricky | D12: 24 | E12: 11 | F12: =IFERROR(ROUND(E12/D12, 3)*100 & "%", "N/A") -> 45,8% | G12: -2 | H12: -3 | I12: 2 | K12: 0 | R12: Matos + Paolo | T12: 6 | U12: 2 | V12: =ROUND(U12/T12, 3)*100 & "%" -> 33,3% | W12: 1 | X12: -3 | Z12: 9 | AA12: Picci | AB12: 504 | AC12: 6 | AD12: 3 | AE12: 3 | AG12: 9 | AH12: =IFERROR(__xludf.DUMMYFUNCTION("""COMPUTED_VALUE"""),"Birra") -> Birra | AI12: =IFERROR(__xludf.DUMMYFUNCTION("""COMPUTED_VALUE"""),4.0) -> 4 | AJ12: =IFERROR(__xludf.DUMMYFUNCTION("""COMPUTED_VALUE"""),"57,1%") -> 57,1% | AK12: =IFERROR(__xludf.DUMMYFUNCTION("""COMPUTED_VALUE"""),2.29) -> 2.29 | AM12: 9 | AN12: =IFERROR(__xludf.DUMMYFUNCTION("""COMPUTED_VALUE"""),"Vesco + Picci") -> Vesco + Picci | AO12: =IFERROR(__xludf.DUMMYFUNCTION("""COMPUTED_VALUE"""),3.0) -> 3 | AP12: =IFERROR(__xludf.DUMMYFUNCTION("""COMPUTED_VALUE"""),"50%") -> 50% | AQ12: =IFERROR(__xludf.DUMMYFUNCTION("""COMPUTED_VALUE"""),1.5) -> 1.5
R13: Bonny + Feli | T13: 6 | U13: 2 | V13: =ROUND(U13/T13, 3)*100 & "%" -> 33,3% | W13: 1 | X13: -4 | Z13: 10 | AA13: Riki | AB13: 484 | AC13: 24 | AD13: 11 | AE13: 13 | AG13: 10 | AH13: =IFERROR(__xludf.DUMMYFUNCTION("""COMPUTED_VALUE"""),"Col") -> Col | AI13: =IFERROR(__xludf.DUMMYFUNCTION("""COMPUTED_VALUE"""),4.0) -> 4 | AJ13: =IFERROR(__xludf.DUMMYFUNCTION("""COMPUTED_VALUE"""),"57,1%") -> 57,1% | AK13: =IFERROR(__xludf.DUMMYFUNCTION("""COMPUTED_VALUE"""),2.29) -> 2.29 | AM13: 10 | AN13: =IFERROR(__xludf.DUMMYFUNCTION("""COMPUTED_VALUE"""),"Filli + Paolo") -> Filli + Paolo | AO13: =IFERROR(__xludf.DUMMYFUNCTION("""COMPUTED_VALUE"""),3.0) -> 3 | AP13: =IFERROR(__xludf.DUMMYFUNCTION("""COMPUTED_VALUE"""),"50%") -> 50% | AQ13: =IFERROR(__xludf.DUMMYFUNCTION("""COMPUTED_VALUE"""),1.5) -> 1.5
B14: Paolo | D14: 40 | E14: 19 | F14: =IFERROR(ROUND(E14/D14, 3)*100 & "%" , "N/A") -> 47,5% | G14: 3 | H14: -6 | I14: 3 | K14: 0 | M14: Legenda stili di gioco | R14: Matos + Gae | T14: 7 | U14: 4 | V14: =ROUND(U14/T14, 3)*100 & "%" -> 57,1% | W14: 2 | X14: -1 | Z14: 11 | AA14: Vezzo | AB14: 482 | AC14: 8 | AD14: 3 | AE14: 5
M15: Spara e spera | N15: Tira a tutta forza senza pensare alla posizione, sperando che qualcosa finisca in buca. | R15: Filli + Paolo | T15: 6 | U15: 3 | V15: =ROUND(U15/T15, 3)*100 & "%" -> 50% | W15: 2 | X15: -1 | Z15: 12 | AA15: Feli | AB15: 459 | AC15: 5 | AD15: 1 | AE15: 4
B16: Birra | D16: 7 | E16: 4 | F16: =IFERROR(ROUND(E16/D16, 3)*100 & "%", "N/A") -> 57,1% | G16: 4 | H16: -3 | I16: 4 | K16: 0 | R16: Vesco + Bonny | T16: 6 | U16: 2 | V16: =ROUND(U16/T16, 3)*100 & "%" -> 33,3% | W16: 1 | X16: -3 | Z16: 13 | AA16: Bonny | AB16: 455 | AC16: 39 | AD16: 14 | AE16: 25
M17: Strategico | N17: Studia ogni angolo con calma, pianifica la serie e preferisce la precisione alla potenza. | R17: Gae + Filli | T17: 8 | U17: 5 | V17: =ROUND(U17/T17, 3)*100 & "%" -> 62,5% | W17: 3 | X17: -1
B18: Col | D18: 7 | E18: 4 | F18: =IFERROR(ROUND(E18/D18, 3)*100 & "%", "N/A") -> 57,1% | G18: -1 | H18: -2 | I18: 2 | K18: 0 | R18: Paolo + Ricky | T18: 5 | U18: 2 | V18: =ROUND(U18/T18, 3)*100 & "%" -> 40% | W18: 2 | X18: -2
M19: Aggressivo | N19: Attacca sempre e cerca l'imbucata a ogni costo, anche su tiri quasi impossibili. | R19: Matos + Bonny | T19: 5 | U19: 2 | V19: =ROUND(U19/T19, 3)*100 & "%" -> 40% | W19: 1 | X19: -2
B20: Filli | D20: 28 | E20: 15 | F20: =IFERROR(ROUND(E20/D20, 3)*100 & "%" , "N/A") -> 53,6% | G20: 2 | H20: -3 | I20: 3 | K20: 0 | R20: Ricky + Vesco + Bonny | T20: 3 | U20: 2 | V20: =ROUND(U20/T20, 3)*100 & "%" -> 66,7% | W20: 2 | X20: -1
M21: Difensivo | N21: Se non ha un tiro facile, preferisce nascondere la bianca e bloccare il gioco dell'avversario. | R21: Francia + Vezzo | T21: 2 | U21: 1 | V21: =ROUND(U21/T21, 3)*100 & "%" -> 50% | W21: 1 | X21: -1
B22: Feli | D22: 5 | E22: 1 | F22: =IFERROR(ROUND(E22/D22, 3)*100 & "%" , "N/A") -> 20% | G22: -4 | H22: -4 | I22: 1 | K22: 0 | R22: Gae + Paolo | T22: 5 | U22: 3 | V22: =ROUND(U22/T22, 3)*100 & "%" -> 60% | W22: 2 | X22: -1
M23: Fine | N23: Cerca tiri difficili a più sponde, combinazioni o effetti scenografici per il gusto della giocata. | R23: Vesco + Matos | T23: 6 | U23: 5 | V23: =ROUND(U23/T23, 3)*100 & "%" -> 83,3% | W23: 4 | X23: -1
B24: Vesco | D24: 21 | E24: 12 | F24: =IFERROR(ROUND(E24/D24, 3)*100 & "%" , "N/A") -> 57,1% | G24: 1 | H24: -3 | I24: 4 | K24: 0 | R24: Paolo + Bonny | T24: 6 | U24: 3 | V24: =ROUND(U24/T24, 3)*100 & "%" -> 50% | W24: 2 | X24: -1
M25: Istintivo | N25: Tira in pochi secondi senza pensarci troppo, affidandosi puramente al colpo d'occhio. | R25: Filli + Francia | T25: 6 | U25: 3 | V25: =ROUND(U25/T25, 3)*100 & "%" -> 50% | W25: 2 | X25: -3
B26: Picci | D26: 6 | E26: 3 | F26: =IFERROR(ROUND(E26/D26, 3)*100 & "%" , "N/A") -> 50% | G26: -1 | H26: -1 | I26: 2 | K26: 0 | R26: Gae + Ricky | T26: 4 | U26: 1 | V26: =ROUND(U26/T26, 3)*100 & "%" -> 25% | W26: 1 | X26: -3
M27: Minimalista | N27: Gioca solo tiri semplici e sicuri a bassa percentuale di rischio, non tenta colpi complessi. | R27: Matos + Ricky | T27: 5 | U27: 2 | V27: =ROUND(U27/T27, 3)*100 & "%" -> 40% | W27: 1 | X27: -2
B28: Vezzo | D28: 8 | E28: 3 | F28: =IFERROR(ROUND(E28/D28, 3)*100 & "%" , "N/A") -> 37,5% | G28: -2 | H28: -2 | I28: 2 | K28: 0 | R28: Bonny + Vezzo | T28: 6 | U28: 2 | V28: =ROUND(U28/T28, 3)*100 & "%" -> 33,3% | W28: 1 | X28: -2
M29: Sculato | N29: Autoesplicativo.

Sheet Partite
B1: A | C1: B | D1: C | E1: D | F1: Vincitore | G1: Elo A | H1: Elo B | I1: Elo C | J1: Elo D | K1: Elo Team 1 | L1: Elo Team 2 | M1: Prob T1 | N1: Var. Base | O1: Nuovo Elo A | P1: Nuovo Elo B | Q1: Nuovo Elo C | R1: Nuovo Elo D
A2: =IF(B2="","", ROW()-1) -> 1 | B2: Bonny | C2: Gae | D2: Francia | E2: Matos | F2: 1 | G2: =IFERROR(__xludf.DUMMYFUNCTION("IF(B2="""","""",ROUND(XLOOKUP(B2, FLATTEN(B$1:E1), FLATTEN(O$1:R1), 500, 0, -1)))"),500.0) -> 500 | H2: =IFERROR(__xludf.DUMMYFUNCTION("IF(C2="""","""",ROUND(XLOOKUP(C2, FLATTEN(B$1:E1), FLATTEN(O$1:R1), 500, 0, -1)))"),500.0) -> 500 | I2: =IFERROR(__xludf.DUMMYFUNCTION("IF(D2="""","""",ROUND(XLOOKUP(D2, FLATTEN(B$1:E1), FLATTEN(O$1:R1), 500, 0, -1)))"),500.0) -> 500 | J2: =IFERROR(__xludf.DUMMYFUNCTION("IF(E2="""","""",ROUND(XLOOKUP(E2, FLATTEN(B$1:E1), FLATTEN(O$1:R1), 500, 0, -1)))"),500.0) -> 500 | K2: =IF(B2="","",ROUND((G2+H2)/2 - ((MAX(G2,H2)-MIN(G2,H2))^2)/1200,0)) -> 500 | L2: =IF(D2="","",ROUND((I2+J2)/2 - ((MAX(I2,J2)-MIN(I2,J2))^2)/1200,0)) -> 500 | M2: =IF(F2="","",ROUND(1 / (1 + 10^((L2-K2)/400)), 2)) -> 0.5 | N2: =IF(F2="","",ROUND(40 * (IF(F2=1, 1, 0) - M2),0)) -> 20 | O2: =IF(F2="","",ROUND(G2 + N2 + IF(F2=1, 3, 0),0)) -> 523 | P2: =IF(F2="","",ROUND(H2 + N2 + IF(F2=1, 3, 0),0)) -> 523 | Q2: =IF(F2="","",ROUND(I2 - N2 + IF(F2=2, 3, 0),0)) -> 480 | R2: =IF(F2="","",ROUND(J2 - N2 + IF(F2=2, 3, 0),0)) -> 480
A3: =IF(B3="","", ROW()-1) -> 2 | B3: Francia | C3: Matos | D3: Bonny | E3: Gae | F3: 1 | G3: =IFERROR(__xludf.DUMMYFUNCTION("IF(B3="""","""",ROUND(XLOOKUP(B3, FLATTEN(B$1:E2), FLATTEN(O$1:R2), 500, 0, -1)))"),480.0) -> 480 | H3: =IFERROR(__xludf.DUMMYFUNCTION("IF(C3="""","""",ROUND(XLOOKUP(C3, FLATTEN(B$1:E2), FLATTEN(O$1:R2), 500, 0, -1)))"),480.0) -> 480 | I3: =IFERROR(__xludf.DUMMYFUNCTION("IF(D3="""","""",ROUND(XLOOKUP(D3, FLATTEN(B$1:E2), FLATTEN(O$1:R2), 500, 0, -1)))"),523.0) -> 523 | J3: =IFERROR(__xludf.DUMMYFUNCTION("IF(E3="""","""",ROUND(XLOOKUP(E3, FLATTEN(B$1:E2), FLATTEN(O$1:R2), 500, 0, -1)))"),523.0) -> 523 | K3: =IF(B3="","",ROUND((G3+H3)/2 - ((MAX(G3,H3)-MIN(G3,H3))^2)/1200,0)) -> 480 | L3: =IF(D3="","",ROUND((I3+J3)/2 - ((MAX(I3,J3)-MIN(I3,J3))^2)/1200,0)) -> 523 | M3: =IF(F3="","",ROUND(1 / (1 + 10^((L3-K3)/400)), 2)) -> 0.44 | N3: =IF(F3="","",ROUND(40 * (IF(F3=1, 1, 0) - M3),0)) -> 22 | O3: =IF(F3="","",ROUND(G3 + N3 + IF(F3=1, 3, 0),0)) -> 505 | P3: =IF(F3="","",ROUND(H3 + N3 + IF(F3=1, 3, 0),0)) -> 505 | Q3: =IF(F3="","",ROUND(I3 - N3 + IF(F3=2, 3, 0),0)) -> 501 | R3: =IF(F3="","",ROUND(J3 - N3 + IF(F3=2, 3, 0),0)) -> 501
A4: =IF(B4="","", ROW()-1) -> 3 | B4: Francia | C4: Matos | D4: Bonny | E4: Gae | F4: 1 | G4: =IFERROR(__xludf.DUMMYFUNCTION("IF(B4="""","""",ROUND(XLOOKUP(B4, FLATTEN(B$1:E3), FLATTEN(O$1:R3), 500, 0, -1)))"),505.0) -> 505 | H4: =IFERROR(__xludf.DUMMYFUNCTION("IF(C4="""","""",ROUND(XLOOKUP(C4, FLATTEN(B$1:E3), FLATTEN(O$1:R3), 500, 0, -1)))"),505.0) -> 505 | I4: =IFERROR(__xludf.DUMMYFUNCTION("IF(D4="""","""",ROUND(XLOOKUP(D4, FLATTEN(B$1:E3), FLATTEN(O$1:R3), 500, 0, -1)))"),501.0) -> 501 | J4: =IFERROR(__xludf.DUMMYFUNCTION("IF(E4="""","""",ROUND(XLOOKUP(E4, FLATTEN(B$1:E3), FLATTEN(O$1:R3), 500, 0, -1)))"),501.0) -> 501 | K4: =IF(B4="","",ROUND((G4+H4)/2 - ((MAX(G4,H4)-MIN(G4,H4))^2)/1200,0)) -> 505 | L4: =IF(D4="","",ROUND((I4+J4)/2 - ((MAX(I4,J4)-MIN(I4,J4))^2)/1200,0)) -> 501 | M4: =IF(F4="","",ROUND(1 / (1 + 10^((L4-K4)/400)), 2)) -> 0.51 | N4: =IF(F4="","",ROUND(40 * (IF(F4=1, 1, 0) - M4),0)) -> 20 | O4: =IF(F4="","",ROUND(G4 + N4 + IF(F4=1, 3, 0),0)) -> 528 | P4: =IF(F4="","",ROUND(H4 + N4 + IF(F4=1, 3, 0),0)) -> 528 | Q4: =IF(F4="","",ROUND(I4 - N4 + IF(F4=2, 3, 0),0)) -> 481 | R4: =IF(F4="","",ROUND(J4 - N4 + IF(F4=2, 3, 0),0)) -> 481
A5: =IF(B5="","", ROW()-1) -> 4 | B5: Francia | C5: Matos | D5: Bonny | E5: Gae | F5: 1 | G5: =IFERROR(__xludf.DUMMYFUNCTION("IF(B5="""","""",ROUND(XLOOKUP(B5, FLATTEN(B$1:E4), FLATTEN(O$1:R4), 500, 0, -1)))"),528.0) -> 528 | H5: =IFERROR(__xludf.DUMMYFUNCTION("IF(C5="""","""",ROUND(XLOOKUP(C5, FLATTEN(B$1:E4), FLATTEN(O$1:R4), 500, 0, -1)))"),528.0) -> 528 | I5: =IFERROR(__xludf.DUMMYFUNCTION("IF(D5="""","""",ROUND(XLOOKUP(D5, FLATTEN(B$1:E4), FLATTEN(O$1:R4), 500, 0, -1)))"),481.0) -> 481 | J5: =IFERROR(__xludf.DUMMYFUNCTION("IF(E5="""","""",ROUND(XLOOKUP(E5, FLATTEN(B$1:E4), FLATTEN(O$1:R4), 500, 0, -1)))"),481.0) -> 481 | K5: =IF(B5="","",ROUND((G5+H5)/2 - ((MAX(G5,H5)-MIN(G5,H5))^2)/1200,0)) -> 528 | L5: =IF(D5="","",ROUND((I5+J5)/2 - ((MAX(I5,J5)-MIN(I5,J5))^2)/1200,0)) -> 481 | M5: =IF(F5="","",ROUND(1 / (1 + 10^((L5-K5)/400)), 2)) -> 0.57 | N5: =IF(F5="","",ROUND(40 * (IF(F5=1, 1, 0) - M5),0)) -> 17 | O5: =IF(F5="","",ROUND(G5 + N5 + IF(F5=1, 3, 0),0)) -> 548 | P5: =IF(F5="","",ROUND(H5 + N5 + IF(F5=1, 3, 0),0)) -> 548 | Q5: =IF(F5="","",ROUND(I5 - N5 + IF(F5=2, 3, 0),0)) -> 464 | R5: =IF(F5="","",ROUND(J5 - N5 + IF(F5=2, 3, 0),0)) -> 464
A6: =IF(B6="","", ROW()-1) -> 5 | B6: Francia | C6: Matos | D6: Bonny | E6: Gae | F6: 1 | G6: =IFERROR(__xludf.DUMMYFUNCTION("IF(B6="""","""",ROUND(XLOOKUP(B6, FLATTEN(B$1:E5), FLATTEN(O$1:R5), 500, 0, -1)))"),548.0) -> 548 | H6: =IFERROR(__xludf.DUMMYFUNCTION("IF(C6="""","""",ROUND(XLOOKUP(C6, FLATTEN(B$1:E5), FLATTEN(O$1:R5), 500, 0, -1)))"),548.0) -> 548 | I6: =IFERROR(__xludf.DUMMYFUNCTION("IF(D6="""","""",ROUND(XLOOKUP(D6, FLATTEN(B$1:E5), FLATTEN(O$1:R5), 500, 0, -1)))"),464.0) -> 464 | J6: =IFERROR(__xludf.DUMMYFUNCTION("IF(E6="""","""",ROUND(XLOOKUP(E6, FLATTEN(B$1:E5), FLATTEN(O$1:R5), 500, 0, -1)))"),464.0) -> 464 | K6: =IF(B6="","",ROUND((G6+H6)/2 - ((MAX(G6,H6)-MIN(G6,H6))^2)/1200,0)) -> 548 | L6: =IF(D6="","",ROUND((I6+J6)/2 - ((MAX(I6,J6)-MIN(I6,J6))^2)/1200,0)) -> 464 | M6: =IF(F6="","",ROUND(1 / (1 + 10^((L6-K6)/400)), 2)) -> 0.62 | N6: =IF(F6="","",ROUND(40 * (IF(F6=1, 1, 0) - M6),0)) -> 15 | O6: =IF(F6="","",ROUND(G6 + N6 + IF(F6=1, 3, 0),0)) -> 566 | P6: =IF(F6="","",ROUND(H6 + N6 + IF(F6=1, 3, 0),0)) -> 566 | Q6: =IF(F6="","",ROUND(I6 - N6 + IF(F6=2, 3, 0),0)) -> 449 | R6: =IF(F6="","",ROUND(J6 - N6 + IF(F6=2, 3, 0),0)) -> 449
A7: =IF(B7="","", ROW()-1) -> 6 | B7: Francia | C7: Matos | D7: Bonny | E7: Gae | F7: 1 | G7: =IFERROR(__xludf.DUMMYFUNCTION("IF(B7="""","""",ROUND(XLOOKUP(B7, FLATTEN(B$1:E6), FLATTEN(O$1:R6), 500, 0, -1)))"),566.0) -> 566 | H7: =IFERROR(__xludf.DUMMYFUNCTION("IF(C7="""","""",ROUND(XLOOKUP(C7, FLATTEN(B$1:E6), FLATTEN(O$1:R6), 500, 0, -1)))"),566.0) -> 566 | I7: =IFERROR(__xludf.DUMMYFUNCTION("IF(D7="""","""",ROUND(XLOOKUP(D7, FLATTEN(B$1:E6), FLATTEN(O$1:R6), 500, 0, -1)))"),449.0) -> 449 | J7: =IFERROR(__xludf.DUMMYFUNCTION("IF(E7="""","""",ROUND(XLOOKUP(E7, FLATTEN(B$1:E6), FLATTEN(O$1:R6), 500, 0, -1)))"),449.0) -> 449 | K7: =IF(B7="","",ROUND((G7+H7)/2 - ((MAX(G7,H7)-MIN(G7,H7))^2)/1200,0)) -> 566 | L7: =IF(D7="","",ROUND((I7+J7)/2 - ((MAX(I7,J7)-MIN(I7,J7))^2)/1200,0)) -> 449 | M7: =IF(F7="","",ROUND(1 / (1 + 10^((L7-K7)/400)), 2)) -> 0.66 | N7: =IF(F7="","",ROUND(40 * (IF(F7=1, 1, 0) - M7),0)) -> 14 | O7: =IF(F7="","",ROUND(G7 + N7 + IF(F7=1, 3, 0),0)) -> 583 | P7: =IF(F7="","",ROUND(H7 + N7 + IF(F7=1, 3, 0),0)) -> 583 | Q7: =IF(F7="","",ROUND(I7 - N7 + IF(F7=2, 3, 0),0)) -> 435 | R7: =IF(F7="","",ROUND(J7 - N7 + IF(F7=2, 3, 0),0)) -> 435
A8: =IF(B8="","", ROW()-1) -> 7 | B8: Francia | C8: Matos | D8: Bonny | E8: Gae | F8: 1 | G8: =IFERROR(__xludf.DUMMYFUNCTION("IF(B8="""","""",ROUND(XLOOKUP(B8, FLATTEN(B$1:E7), FLATTEN(O$1:R7), 500, 0, -1)))"),583.0) -> 583 | H8: =IFERROR(__xludf.DUMMYFUNCTION("IF(C8="""","""",ROUND(XLOOKUP(C8, FLATTEN(B$1:E7), FLATTEN(O$1:R7), 500, 0, -1)))"),583.0) -> 583 | I8: =IFERROR(__xludf.DUMMYFUNCTION("IF(D8="""","""",ROUND(XLOOKUP(D8, FLATTEN(B$1:E7), FLATTEN(O$1:R7), 500, 0, -1)))"),435.0) -> 435 | J8: =IFERROR(__xludf.DUMMYFUNCTION("IF(E8="""","""",ROUND(XLOOKUP(E8, FLATTEN(B$1:E7), FLATTEN(O$1:R7), 500, 0, -1)))"),435.0) -> 435 | K8: =IF(B8="","",ROUND((G8+H8)/2 - ((MAX(G8,H8)-MIN(G8,H8))^2)/1200,0)) -> 583 | L8: =IF(D8="","",ROUND((I8+J8)/2 - ((MAX(I8,J8)-MIN(I8,J8))^2)/1200,0)) -> 435 | M8: =IF(F8="","",ROUND(1 / (1 + 10^((L8-K8)/400)), 2)) -> 0.7 | N8: =IF(F8="","",ROUND(40 * (IF(F8=1, 1, 0) - M8),0)) -> 12 | O8: =IF(F8="","",ROUND(G8 + N8 + IF(F8=1, 3, 0),0)) -> 598 | P8: =IF(F8="","",ROUND(H8 + N8 + IF(F8=1, 3, 0),0)) -> 598 | Q8: =IF(F8="","",ROUND(I8 - N8 + IF(F8=2, 3, 0),0)) -> 423 | R8: =IF(F8="","",ROUND(J8 - N8 + IF(F8=2, 3, 0),0)) -> 423
A9: =IF(B9="","", ROW()-1) -> 8 | B9: Francia | C9: Matos | D9: Bonny | E9: Gae | F9: 1 | G9: =IFERROR(__xludf.DUMMYFUNCTION("IF(B9="""","""",ROUND(XLOOKUP(B9, FLATTEN(B$1:E8), FLATTEN(O$1:R8), 500, 0, -1)))"),598.0) -> 598 | H9: =IFERROR(__xludf.DUMMYFUNCTION("IF(C9="""","""",ROUND(XLOOKUP(C9, FLATTEN(B$1:E8), FLATTEN(O$1:R8), 500, 0, -1)))"),598.0) -> 598 | I9: =IFERROR(__xludf.DUMMYFUNCTION("IF(D9="""","""",ROUND(XLOOKUP(D9, FLATTEN(B$1:E8), FLATTEN(O$1:R8), 500, 0, -1)))"),423.0) -> 423 | J9: =IFERROR(__xludf.DUMMYFUNCTION("IF(E9="""","""",ROUND(XLOOKUP(E9, FLATTEN(B$1:E8), FLATTEN(O$1:R8), 500, 0, -1)))"),423.0) -> 423 | K9: =IF(B9="","",ROUND((G9+H9)/2 - ((MAX(G9,H9)-MIN(G9,H9))^2)/1200,0)) -> 598 | L9: =IF(D9="","",ROUND((I9+J9)/2 - ((MAX(I9,J9)-MIN(I9,J9))^2)/1200,0)) -> 423 | M9: =IF(F9="","",ROUND(1 / (1 + 10^((L9-K9)/400)), 2)) -> 0.73 | N9: =IF(F9="","",ROUND(40 * (IF(F9=1, 1, 0) - M9),0)) -> 11 | O9: =IF(F9="","",ROUND(G9 + N9 + IF(F9=1, 3, 0),0)) -> 612 | P9: =IF(F9="","",ROUND(H9 + N9 + IF(F9=1, 3, 0),0)) -> 612 | Q9: =IF(F9="","",ROUND(I9 - N9 + IF(F9=2, 3, 0),0)) -> 412 | R9: =IF(F9="","",ROUND(J9 - N9 + IF(F9=2, 3, 0),0)) -> 412
A10: =IF(B10="","", ROW()-1) -> 9 | B10: Bonny | C10: Gae | D10: Francia | E10: Matos | F10: 1 | G10: =IFERROR(__xludf.DUMMYFUNCTION("IF(B10="""","""",ROUND(XLOOKUP(B10, FLATTEN(B$1:E9), FLATTEN(O$1:R9), 500, 0, -1)))"),412.0) -> 412 | H10: =IFERROR(__xludf.DUMMYFUNCTION("IF(C10="""","""",ROUND(XLOOKUP(C10, FLATTEN(B$1:E9), FLATTEN(O$1:R9), 500, 0, -1)))"),412.0) -> 412 | I10: =IFERROR(__xludf.DUMMYFUNCTION("IF(D10="""","""",ROUND(XLOOKUP(D10, FLATTEN(B$1:E9), FLATTEN(O$1:R9), 500, 0, -1)))"),612.0) -> 612 | J10: =IFERROR(__xludf.DUMMYFUNCTION("IF(E10="""","""",ROUND(XLOOKUP(E10, FLATTEN(B$1:E9), FLATTEN(O$1:R9), 500, 0, -1)))"),612.0) -> 612 | K10: =IF(B10="","",ROUND((G10+H10)/2 - ((MAX(G10,H10)-MIN(G10,H10))^2)/1200,0)) -> 412 | L10: =IF(D10="","",ROUND((I10+J10)/2 - ((MAX(I10,J10)-MIN(I10,J10))^2)/1200,0)) -> 612 | M10: =IF(F10="","",ROUND(1 / (1 + 10^((L10-K10)/400)), 2)) -> 0.24 | N10: =IF(F10="","",ROUND(40 * (IF(F10=1, 1, 0) - M10),0)) -> 30 | O10: =IF(F10="","",ROUND(G10 + N10 + IF(F10=1, 3, 0),0)) -> 445 | P10: =IF(F10="","",ROUND(H10 + N10 + IF(F10=1, 3, 0),0)) -> 445 | Q10: =IF(F10="","",ROUND(I10 - N10 + IF(F10=2, 3, 0),0)) -> 582 | R10: =IF(F10="","",ROUND(J10 - N10 + IF(F10=2, 3, 0),0)) -> 582
A11: =IF(B11="","", ROW()-1) -> 10 | B11: Paolo | C11: Francia | D11: Birra | E11: Gae | F11: 1 | G11: =IFERROR(__xludf.DUMMYFUNCTION("IF(B11="""","""",ROUND(XLOOKUP(B11, FLATTEN(B$1:E10), FLATTEN(O$1:R10), 500, 0, -1)))"),500.0) -> 500 | H11: =IFERROR(__xludf.DUMMYFUNCTION("IF(C11="""","""",ROUND(XLOOKUP(C11, FLATTEN(B$1:E10), FLATTEN(O$1:R10), 500, 0, -1)))"),582.0) -> 582 | I11: =IFERROR(__xludf.DUMMYFUNCTION("IF(D11="""","""",ROUND(XLOOKUP(D11, FLATTEN(B$1:E10), FLATTEN(O$1:R10), 500, 0, -1)))"),500.0) -> 500 | J11: =IFERROR(__xludf.DUMMYFUNCTION("IF(E11="""","""",ROUND(XLOOKUP(E11, FLATTEN(B$1:E10), FLATTEN(O$1:R10), 500, 0, -1)))"),445.0) -> 445 | K11: =IF(B11="","",ROUND((G11+H11)/2 - ((MAX(G11,H11)-MIN(G11,H11))^2)/1200,0)) -> 535 | L11: =IF(D11="","",ROUND((I11+J11)/2 - ((MAX(I11,J11)-MIN(I11,J11))^2)/1200,0)) -> 470 | M11: =IF(F11="","",ROUND(1 / (1 + 10^((L11-K11)/400)), 2)) -> 0.59 | N11: =IF(F11="","",ROUND(40 * (IF(F11=1, 1, 0) - M11),0)) -> 16 | O11: =IF(F11="","",ROUND(G11 + N11 + IF(F11=1, 3, 0),0)) -> 519 | P11: =IF(F11="","",ROUND(H11 + N11 + IF(F11=1, 3, 0),0)) -> 601 | Q11: =IF(F11="","",ROUND(I11 - N11 + IF(F11=2, 3, 0),0)) -> 484 | R11: =IF(F11="","",ROUND(J11 - N11 + IF(F11=2, 3, 0),0)) -> 429
A12: =IF(B12="","", ROW()-1) -> 11 | B12: Riki | C12: Col | D12: Matos | E12: Filli | F12: 1 | G12: =IFERROR(__xludf.DUMMYFUNCTION("IF(B12="""","""",ROUND(XLOOKUP(B12, FLATTEN(B$1:E11), FLATTEN(O$1:R11), 500, 0, -1)))"),500.0) -> 500 | H12: =IFERROR(__xludf.DUMMYFUNCTION("IF(C12="""","""",ROUND(XLOOKUP(C12, FLATTEN(B$1:E11), FLATTEN(O$1:R11), 500, 0, -1)))"),500.0) -> 500 | I12: =IFERROR(__xludf.DUMMYFUNCTION("IF(D12="""","""",ROUND(XLOOKUP(D12, FLATTEN(B$1:E11), FLATTEN(O$1:R11), 500, 0, -1)))"),582.0) -> 582 | J12: =IFERROR(__xludf.DUMMYFUNCTION("IF(E12="""","""",ROUND(XLOOKUP(E12, FLATTEN(B$1:E11), FLATTEN(O$1:R11), 500, 0, -1)))"),500.0) -> 500 | K12: =IF(B12="","",ROUND((G12+H12)/2 - ((MAX(G12,H12)-MIN(G12,H12))^2)/1200,0)) -> 500 | L12: =IF(D12="","",ROUND((I12+J12)/2 - ((MAX(I12,J12)-MIN(I12,J12))^2)/1200,0)) -> 535 | M12: =IF(F12="","",ROUND(1 / (1 + 10^((L12-K12)/400)), 2)) -> 0.45 | N12: =IF(F12="","",ROUND(40 * (IF(F12=1, 1, 0) - M12),0)) -> 22 | O12: =IF(F12="","",ROUND(G12 + N12 + IF(F12=1, 3, 0),0)) -> 525 | P12: =IF(F12="","",ROUND(H12 + N12 + IF(F12=1, 3, 0),0)) -> 525 | Q12: =IF(F12="","",ROUND(I12 - N12 + IF(F12=2, 3, 0),0)) -> 560 | R12: =IF(F12="","",ROUND(J12 - N12 + IF(F12=2, 3, 0),0)) -> 478
A13: =IF(B13="","", ROW()-1) -> 12 | B13: Riki | C13: Col | D13: Birra | E13: Gae | F13: 1 | G13: =IFERROR(__xludf.DUMMYFUNCTION("IF(B13="""","""",ROUND(XLOOKUP(B13, FLATTEN(B$1:E12), FLATTEN(O$1:R12), 500, 0, -1)))"),525.0) -> 525 | H13: =IFERROR(__xludf.DUMMYFUNCTION("IF(C13="""","""",ROUND(XLOOKUP(C13, FLATTEN(B$1:E12), FLATTEN(O$1:R12), 500, 0, -1)))"),525.0) -> 525 | I13: =IFERROR(__xludf.DUMMYFUNCTION("IF(D13="""","""",ROUND(XLOOKUP(D13, FLATTEN(B$1:E12), FLATTEN(O$1:R12), 500, 0, -1)))"),484.0) -> 484 | J13: =IFERROR(__xludf.DUMMYFUNCTION("IF(E13="""","""",ROUND(XLOOKUP(E13, FLATTEN(B$1:E12), FLATTEN(O$1:R12), 500, 0, -1)))"),429.0) -> 429 | K13: =IF(B13="","",ROUND((G13+H13)/2 - ((MAX(G13,H13)-MIN(G13,H13))^2)/1200,0)) -> 525 | L13: =IF(D13="","",ROUND((I13+J13)/2 - ((MAX(I13,J13)-MIN(I13,J13))^2)/1200,0)) -> 454 | M13: =IF(F13="","",ROUND(1 / (1 + 10^((L13-K13)/400)), 2)) -> 0.6 | N13: =IF(F13="","",ROUND(40 * (IF(F13=1, 1, 0) - M13),0)) -> 16 | O13: =IF(F13="","",ROUND(G13 + N13 + IF(F13=1, 3, 0),0)) -> 544 | P13: =IF(F13="","",ROUND(H13 + N13 + IF(F13=1, 3, 0),0)) -> 544 | Q13: =IF(F13="","",ROUND(I13 - N13 + IF(F13=2, 3, 0),0)) -> 468 | R13: =IF(F13="","",ROUND(J13 - N13 + IF(F13=2, 3, 0),0)) -> 413
A14: =IF(B14="","", ROW()-1) -> 13 | B14: Matos | C14: Filli | D14: Paolo | E14: Francia | F14: 1 | G14: =IFERROR(__xludf.DUMMYFUNCTION("IF(B14="""","""",ROUND(XLOOKUP(B14, FLATTEN(B$1:E13), FLATTEN(O$1:R13), 500, 0, -1)))"),560.0) -> 560 | H14: =IFERROR(__xludf.DUMMYFUNCTION("IF(C14="""","""",ROUND(XLOOKUP(C14, FLATTEN(B$1:E13), FLATTEN(O$1:R13), 500, 0, -1)))"),478.0) -> 478 | I14: =IFERROR(__xludf.DUMMYFUNCTION("IF(D14="""","""",ROUND(XLOOKUP(D14, FLATTEN(B$1:E13), FLATTEN(O$1:R13), 500, 0, -1)))"),519.0) -> 519 | J14: =IFERROR(__xludf.DUMMYFUNCTION("IF(E14="""","""",ROUND(XLOOKUP(E14, FLATTEN(B$1:E13), FLATTEN(O$1:R13), 500, 0, -1)))"),601.0) -> 601 | K14: =IF(B14="","",ROUND((G14+H14)/2 - ((MAX(G14,H14)-MIN(G14,H14))^2)/1200,0)) -> 513 | L14: =IF(D14="","",ROUND((I14+J14)/2 - ((MAX(I14,J14)-MIN(I14,J14))^2)/1200,0)) -> 554 | M14: =IF(F14="","",ROUND(1 / (1 + 10^((L14-K14)/400)), 2)) -> 0.44 | N14: =IF(F14="","",ROUND(40 * (IF(F14=1, 1, 0) - M14),0)) -> 22 | O14: =IF(F14="","",ROUND(G14 + N14 + IF(F14=1, 3, 0),0)) -> 585 | P14: =IF(F14="","",ROUND(H14 + N14 + IF(F14=1, 3, 0),0)) -> 503 | Q14: =IF(F14="","",ROUND(I14 - N14 + IF(F14=2, 3, 0),0)) -> 497 | R14: =IF(F14="","",ROUND(J14 - N14 + IF(F14=2, 3, 0),0)) -> 579
A15: =IF(B15="","", ROW()-1) -> 14 | B15: Matos | C15: Filli | D15: Birra | E15: Gae | F15: 1 | G15: =IFERROR(__xludf.DUMMYFUNCTION("IF(B15="""","""",ROUND(XLOOKUP(B15, FLATTEN(B$1:E14), FLATTEN(O$1:R14), 500, 0, -1)))"),585.0) -> 585 | H15: =IFERROR(__xludf.DUMMYFUNCTION("IF(C15="""","""",ROUND(XLOOKUP(C15, FLATTEN(B$1:E14), FLATTEN(O$1:R14), 500, 0, -1)))"),503.0) -> 503 | I15: =IFERROR(__xludf.DUMMYFUNCTION("IF(D15="""","""",ROUND(XLOOKUP(D15, FLATTEN(B$1:E14), FLATTEN(O$1:R14), 500, 0, -1)))"),468.0) -> 468 | J15: =IFERROR(__xludf.DUMMYFUNCTION("IF(E15="""","""",ROUND(XLOOKUP(E15, FLATTEN(B$1:E14), FLATTEN(O$1:R14), 500, 0, -1)))"),413.0) -> 413 | K15: =IF(B15="","",ROUND((G15+H15)/2 - ((MAX(G15,H15)-MIN(G15,H15))^2)/1200,0)) -> 538 | L15: =IF(D15="","",ROUND((I15+J15)/2 - ((MAX(I15,J15)-MIN(I15,J15))^2)/1200,0)) -> 438 | M15: =IF(F15="","",ROUND(1 / (1 + 10^((L15-K15)/400)), 2)) -> 0.64 | N15: =IF(F15="","",ROUND(40 * (IF(F15=1, 1, 0) - M15),0)) -> 14 | O15: =IF(F15="","",ROUND(G15 + N15 + IF(F15=1, 3, 0),0)) -> 602 | P15: =IF(F15="","",ROUND(H15 + N15 + IF(F15=1, 3, 0),0)) -> 520 | Q15: =IF(F15="","",ROUND(I15 - N15 + IF(F15=2, 3, 0),0)) -> 454 | R15: =IF(F15="","",ROUND(J15 - N15 + IF(F15=2, 3, 0),0)) -> 399
A16: =IF(B16="","", ROW()-1) -> 15 | B16: Paolo | C16: Francia | D16: Riki | E16: Col | F16: 1 | G16: =IFERROR(__xludf.DUMMYFUNCTION("IF(B16="""","""",ROUND(XLOOKUP(B16, FLATTEN(B$1:E15), FLATTEN(O$1:R15), 500, 0, -1)))"),497.0) -> 497 | H16: =IFERROR(__xludf.DUMMYFUNCTION("IF(C16="""","""",ROUND(XLOOKUP(C16, FLATTEN(B$1:E15), FLATTEN(O$1:R15), 500, 0, -1)))"),579.0) -> 579 | I16: =IFERROR(__xludf.DUMMYFUNCTION("IF(D16="""","""",ROUND(XLOOKUP(D16, FLATTEN(B$1:E15), FLATTEN(O$1:R15), 500, 0, -1)))"),544.0) -> 544 | J16: =IFERROR(__xludf.DUMMYFUNCTION("IF(E16="""","""",ROUND(XLOOKUP(E16, FLATTEN(B$1:E15), FLATTEN(O$1:R15), 500, 0, -1)))"),544.0) -> 544 | K16: =IF(B16="","",ROUND((G16+H16)/2 - ((MAX(G16,H16)-MIN(G16,H16))^2)/1200,0)) -> 532 | L16: =IF(D16="","",ROUND((I16+J16)/2 - ((MAX(I16,J16)-MIN(I16,J16))^2)/1200,0)) -> 544 | M16: =IF(F16="","",ROUND(1 / (1 + 10^((L16-K16)/400)), 2)) -> 0.48 | N16: =IF(F16="","",ROUND(40 * (IF(F16=1, 1, 0) - M16),0)) -> 21 | O16: =IF(F16="","",ROUND(G16 + N16 + IF(F16=1, 3, 0),0)) -> 521 | P16: =IF(F16="","",ROUND(H16 + N16 + IF(F16=1, 3, 0),0)) -> 603 | Q16: =IF(F16="","",ROUND(I16 - N16 + IF(F16=2, 3, 0),0)) -> 523 | R16: =IF(F16="","",ROUND(J16 - N16 + IF(F16=2, 3, 0),0)) -> 523
A17: =IF(B17="","", ROW()-1) -> 16 | B17: Birra | C17: Gae | D17: Riki | E17: Col | F17: 1 | G17: =IFERROR(__xludf.DUMMYFUNCTION("IF(B17="""","""",ROUND(XLOOKUP(B17, FLATTEN(B$1:E16), FLATTEN(O$1:R16), 500, 0, -1)))"),454.0) -> 454 | H17: =IFERROR(__xludf.DUMMYFUNCTION("IF(C17="""","""",ROUND(XLOOKUP(C17, FLATTEN(B$1:E16), FLATTEN(O$1:R16), 500, 0, -1)))"),399.0) -> 399 | I17: =IFERROR(__xludf.DUMMYFUNCTION("IF(D17="""","""",ROUND(XLOOKUP(D17, FLATTEN(B$1:E16), FLATTEN(O$1:R16), 500, 0, -1)))"),523.0) -> 523 | J17: =IFERROR(__xludf.DUMMYFUNCTION("IF(E17="""","""",ROUND(XLOOKUP(E17, FLATTEN(B$1:E16), FLATTEN(O$1:R16), 500, 0, -1)))"),523.0) -> 523 | K17: =IF(B17="","",ROUND((G17+H17)/2 - ((MAX(G17,H17)-MIN(G17,H17))^2)/1200,0)) -> 424 | L17: =IF(D17="","",ROUND((I17+J17)/2 - ((MAX(I17,J17)-MIN(I17,J17))^2)/1200,0)) -> 523 | M17: =IF(F17="","",ROUND(1 / (1 + 10^((L17-K17)/400)), 2)) -> 0.36 | N17: =IF(F17="","",ROUND(40 * (IF(F17=1, 1, 0) - M17),0)) -> 26 | O17: =IF(F17="","",ROUND(G17 + N17 + IF(F17=1, 3, 0),0)) -> 483 | P17: =IF(F17="","",ROUND(H17 + N17 + IF(F17=1, 3, 0),0)) -> 428 | Q17: =IF(F17="","",ROUND(I17 - N17 + IF(F17=2, 3, 0),0)) -> 497 | R17: =IF(F17="","",ROUND(J17 - N17 + IF(F17=2, 3, 0),0)) -> 497
A18: =IF(B18="","", ROW()-1) -> 17 | B18: Paolo | C18: Francia | D18: Matos | E18: Filli | F18: 1 | G18: =IFERROR(__xludf.DUMMYFUNCTION("IF(B18="""","""",ROUND(XLOOKUP(B18, FLATTEN(B$1:E17), FLATTEN(O$1:R17), 500, 0, -1)))"),521.0) -> 521 | H18: =IFERROR(__xludf.DUMMYFUNCTION("IF(C18="""","""",ROUND(XLOOKUP(C18, FLATTEN(B$1:E17), FLATTEN(O$1:R17), 500, 0, -1)))"),603.0) -> 603 | I18: =IFERROR(__xludf.DUMMYFUNCTION("IF(D18="""","""",ROUND(XLOOKUP(D18, FLATTEN(B$1:E17), FLATTEN(O$1:R17), 500, 0, -1)))"),602.0) -> 602 | J18: =IFERROR(__xludf.DUMMYFUNCTION("IF(E18="""","""",ROUND(XLOOKUP(E18, FLATTEN(B$1:E17), FLATTEN(O$1:R17), 500, 0, -1)))"),520.0) -> 520 | K18: =IF(B18="","",ROUND((G18+H18)/2 - ((MAX(G18,H18)-MIN(G18,H18))^2)/1200,0)) -> 556 | L18: =IF(D18="","",ROUND((I18+J18)/2 - ((MAX(I18,J18)-MIN(I18,J18))^2)/1200,0)) -> 555 | M18: =IF(F18="","",ROUND(1 / (1 + 10^((L18-K18)/400)), 2)) -> 0.5 | N18: =IF(F18="","",ROUND(40 * (IF(F18=1, 1, 0) - M18),0)) -> 20 | O18: =IF(F18="","",ROUND(G18 + N18 + IF(F18=1, 3, 0),0)) -> 544 | P18: =IF(F18="","",ROUND(H18 + N18 + IF(F18=1, 3, 0),0)) -> 626 | Q18: =IF(F18="","",ROUND(I18 - N18 + IF(F18=2, 3, 0),0)) -> 582 | R18: =IF(F18="","",ROUND(J18 - N18 + IF(F18=2, 3, 0),0)) -> 500
A19: =IF(B19="","", ROW()-1) -> 18 | B19: Birra | C19: Gae | D19: Paolo | E19: Francia | F19: 1 | G19: =IFERROR(__xludf.DUMMYFUNCTION("IF(B19="""","""",ROUND(XLOOKUP(B19, FLATTEN(B$1:E18), FLATTEN(O$1:R18), 500, 0, -1)))"),483.0) -> 483 | H19: =IFERROR(__xludf.DUMMYFUNCTION("IF(C19="""","""",ROUND(XLOOKUP(C19, FLATTEN(B$1:E18), FLATTEN(O$1:R18), 500, 0, -1)))"),428.0) -> 428 | I19: =IFERROR(__xludf.DUMMYFUNCTION("IF(D19="""","""",ROUND(XLOOKUP(D19, FLATTEN(B$1:E18), FLATTEN(O$1:R18), 500, 0, -1)))"),544.0) -> 544 | J19: =IFERROR(__xludf.DUMMYFUNCTION("IF(E19="""","""",ROUND(XLOOKUP(E19, FLATTEN(B$1:E18), FLATTEN(O$1:R18), 500, 0, -1)))"),626.0) -> 626 | K19: =IF(B19="","",ROUND((G19+H19)/2 - ((MAX(G19,H19)-MIN(G19,H19))^2)/1200,0)) -> 453 | L19: =IF(D19="","",ROUND((I19+J19)/2 - ((MAX(I19,J19)-MIN(I19,J19))^2)/1200,0)) -> 579 | M19: =IF(F19="","",ROUND(1 / (1 + 10^((L19-K19)/400)), 2)) -> 0.33 | N19: =IF(F19="","",ROUND(40 * (IF(F19=1, 1, 0) - M19),0)) -> 27 | O19: =IF(F19="","",ROUND(G19 + N19 + IF(F19=1, 3, 0),0)) -> 513 | P19: =IF(F19="","",ROUND(H19 + N19 + IF(F19=1, 3, 0),0)) -> 458 | Q19: =IF(F19="","",ROUND(I19 - N19 + IF(F19=2, 3, 0),0)) -> 517 | R19: =IF(F19="","",ROUND(J19 - N19 + IF(F19=2, 3, 0),0)) -> 599
A20: =IF(B20="","", ROW()-1) -> 19 | B20: Riki | C20: Col | D20: Matos | E20: Filli | F20: 1 | G20: =IFERROR(__xludf.DUMMYFUNCTION("IF(B20="""","""",ROUND(XLOOKUP(B20, FLATTEN(B$1:E19), FLATTEN(O$1:R19), 500, 0, -1)))"),497.0) -> 497 | H20: =IFERROR(__xludf.DUMMYFUNCTION("IF(C20="""","""",ROUND(XLOOKUP(C20, FLATTEN(B$1:E19), FLATTEN(O$1:R19), 500, 0, -1)))"),497.0) -> 497 | I20: =IFERROR(__xludf.DUMMYFUNCTION("IF(D20="""","""",ROUND(XLOOKUP(D20, FLATTEN(B$1:E19), FLATTEN(O$1:R19), 500, 0, -1)))"),582.0) -> 582 | J20: =IFERROR(__xludf.DUMMYFUNCTION("IF(E20="""","""",ROUND(XLOOKUP(E20, FLATTEN(B$1:E19), FLATTEN(O$1:R19), 500, 0, -1)))"),500.0) -> 500 | K20: =IF(B20="","",ROUND((G20+H20)/2 - ((MAX(G20,H20)-MIN(G20,H20))^2)/1200,0)) -> 497 | L20: =IF(D20="","",ROUND((I20+J20)/2 - ((MAX(I20,J20)-MIN(I20,J20))^2)/1200,0)) -> 535 | M20: =IF(F20="","",ROUND(1 / (1 + 10^((L20-K20)/400)), 2)) -> 0.45 | N20: =IF(F20="","",ROUND(40 * (IF(F20=1, 1, 0) - M20),0)) -> 22 | O20: =IF(F20="","",ROUND(G20 + N20 + IF(F20=1, 3, 0),0)) -> 522 | P20: =IF(F20="","",ROUND(H20 + N20 + IF(F20=1, 3, 0),0)) -> 522 | Q20: =IF(F20="","",ROUND(I20 - N20 + IF(F20=2, 3, 0),0)) -> 560 | R20: =IF(F20="","",ROUND(J20 - N20 + IF(F20=2, 3, 0),0)) -> 478
A21: =IF(B21="","", ROW()-1) -> 20 | B21: Birra | C21: Gae | D21: Matos | E21: Filli | F21: 1 | G21: =IFERROR(__xludf.DUMMYFUNCTION("IF(B21="""","""",ROUND(XLOOKUP(B21, FLATTEN(B$1:E20), FLATTEN(O$1:R20), 500, 0, -1)))"),513.0) -> 513 | H21: =IFERROR(__xludf.DUMMYFUNCTION("IF(C21="""","""",ROUND(XLOOKUP(C21, FLATTEN(B$1:E20), FLATTEN(O$1:R20), 500, 0, -1)))"),458.0) -> 458 | I21: =IFERROR(__xludf.DUMMYFUNCTION("IF(D21="""","""",ROUND(XLOOKUP(D21, FLATTEN(B$1:E20), FLATTEN(O$1:R20), 500, 0, -1)))"),560.0) -> 560 | J21: =IFERROR(__xludf.DUMMYFUNCTION("IF(E21="""","""",ROUND(XLOOKUP(E21, FLATTEN(B$1:E20), FLATTEN(O$1:R20), 500, 0, -1)))"),478.0) -> 478 | K21: =IF(B21="","",ROUND((G21+H21)/2 - ((MAX(G21,H21)-MIN(G21,H21))^2)/1200,0)) -> 483 | L21: =IF(D21="","",ROUND((I21+J21)/2 - ((MAX(I21,J21)-MIN(I21,J21))^2)/1200,0)) -> 513 | M21: =IF(F21="","",ROUND(1 / (1 + 10^((L21-K21)/400)), 2)) -> 0.46 | N21: =IF(F21="","",ROUND(40 * (IF(F21=1, 1, 0) - M21),0)) -> 22 | O21: =IF(F21="","",ROUND(G21 + N21 + IF(F21=1, 3, 0),0)) -> 538 | P21: =IF(F21="","",ROUND(H21 + N21 + IF(F21=1, 3, 0),0)) -> 483 | Q21: =IF(F21="","",ROUND(I21 - N21 + IF(F21=2, 3, 0),0)) -> 538 | R21: =IF(F21="","",ROUND(J21 - N21 + IF(F21=2, 3, 0),0)) -> 456
A22: =IF(B22="","", ROW()-1) -> 21 | B22: Riki | C22: Col | D22: Paolo | E22: Francia | F22: 1 | G22: =IFERROR(__xludf.DUMMYFUNCTION("IF(B22="""","""",ROUND(XLOOKUP(B22, FLATTEN(B$1:E21), FLATTEN(O$1:R21), 500, 0, -1)))"),522.0) -> 522 | H22: =IFERROR(__xludf.DUMMYFUNCTION("IF(C22="""","""",ROUND(XLOOKUP(C22, FLATTEN(B$1:E21), FLATTEN(O$1:R21), 500, 0, -1)))"),522.0) -> 522 | I22: =IFERROR(__xludf.DUMMYFUNCTION("IF(D22="""","""",ROUND(XLOOKUP(D22, FLATTEN(B$1:E21), FLATTEN(O$1:R21), 500, 0, -1)))"),517.0) -> 517 | J22: =IFERROR(__xludf.DUMMYFUNCTION("IF(E22="""","""",ROUND(XLOOKUP(E22, FLATTEN(B$1:E21), FLATTEN(O$1:R21), 500, 0, -1)))"),599.0) -> 599 | K22: =IF(B22="","",ROUND((G22+H22)/2 - ((MAX(G22,H22)-MIN(G22,H22))^2)/1200,0)) -> 522 | L22: =IF(D22="","",ROUND((I22+J22)/2 - ((MAX(I22,J22)-MIN(I22,J22))^2)/1200,0)) -> 552 | M22: =IF(F22="","",ROUND(1 / (1 + 10^((L22-K22)/400)), 2)) -> 0.46 | N22: =IF(F22="","",ROUND(40 * (IF(F22=1, 1, 0) - M22),0)) -> 22 | O22: =IF(F22="","",ROUND(G22 + N22 + IF(F22=1, 3, 0),0)) -> 547 | P22: =IF(F22="","",ROUND(H22 + N22 + IF(F22=1, 3, 0),0)) -> 547 | Q22: =IF(F22="","",ROUND(I22 - N22 + IF(F22=2, 3, 0),0)) -> 495 | R22: =IF(F22="","",ROUND(J22 - N22 + IF(F22=2, 3, 0),0)) -> 577
A23: =IF(B23="","", ROW()-1) -> 22 | B23: Birra | C23: Gae | D23: Riki | E23: Col | F23: 1 | G23: =IFERROR(__xludf.DUMMYFUNCTION("IF(B23="""","""",ROUND(XLOOKUP(B23, FLATTEN(B$1:E22), FLATTEN(O$1:R22), 500, 0, -1)))"),538.0) -> 538 | H23: =IFERROR(__xludf.DUMMYFUNCTION("IF(C23="""","""",ROUND(XLOOKUP(C23, FLATTEN(B$1:E22), FLATTEN(O$1:R22), 500, 0, -1)))"),483.0) -> 483 | I23: =IFERROR(__xludf.DUMMYFUNCTION("IF(D23="""","""",ROUND(XLOOKUP(D23, FLATTEN(B$1:E22), FLATTEN(O$1:R22), 500, 0, -1)))"),547.0) -> 547 | J23: =IFERROR(__xludf.DUMMYFUNCTION("IF(E23="""","""",ROUND(XLOOKUP(E23, FLATTEN(B$1:E22), FLATTEN(O$1:R22), 500, 0, -1)))"),547.0) -> 547 | K23: =IF(B23="","",ROUND((G23+H23)/2 - ((MAX(G23,H23)-MIN(G23,H23))^2)/1200,0)) -> 508 | L23: =IF(D23="","",ROUND((I23+J23)/2 - ((MAX(I23,J23)-MIN(I23,J23))^2)/1200,0)) -> 547 | M23: =IF(F23="","",ROUND(1 / (1 + 10^((L23-K23)/400)), 2)) -> 0.44 | N23: =IF(F23="","",ROUND(40 * (IF(F23=1, 1, 0) - M23),0)) -> 22 | O23: =IF(F23="","",ROUND(G23 + N23 + IF(F23=1, 3, 0),0)) -> 563 | P23: =IF(F23="","",ROUND(H23 + N23 + IF(F23=1, 3, 0),0)) -> 508 | Q23: =IF(F23="","",ROUND(I23 - N23 + IF(F23=2, 3, 0),0)) -> 525 | R23: =IF(F23="","",ROUND(J23 - N23 + IF(F23=2, 3, 0),0)) -> 525
A24: =IF(B24="","", ROW()-1) -> 23 | B24: Matos | C24: Filli | D24: Paolo | E24: Francia | F24: 1 | G24: =IFERROR(__xludf.DUMMYFUNCTION("IF(B24="""","""",ROUND(XLOOKUP(B24, FLATTEN(B$1:E23), FLATTEN(O$1:R23), 500, 0, -1)))"),538.0) -> 538 | H24: =IFERROR(__xludf.DUMMYFUNCTION("IF(C24="""","""",ROUND(XLOOKUP(C24, FLATTEN(B$1:E23), FLATTEN(O$1:R23), 500, 0, -1)))"),456.0) -> 456 | I24: =IFERROR(__xludf.DUMMYFUNCTION("IF(D24="""","""",ROUND(XLOOKUP(D24, FLATTEN(B$1:E23), FLATTEN(O$1:R23), 500, 0, -1)))"),495.0) -> 495 | J24: =IFERROR(__xludf.DUMMYFUNCTION("IF(E24="""","""",ROUND(XLOOKUP(E24, FLATTEN(B$1:E23), FLATTEN(O$1:R23), 500, 0, -1)))"),577.0) -> 577 | K24: =IF(B24="","",ROUND((G24+H24)/2 - ((MAX(G24,H24)-MIN(G24,H24))^2)/1200,0)) -> 491 | L24: =IF(D24="","",ROUND((I24+J24)/2 - ((MAX(I24,J24)-MIN(I24,J24))^2)/1200,0)) -> 530 | M24: =IF(F24="","",ROUND(1 / (1 + 10^((L24-K24)/400)), 2)) -> 0.44 | N24: =IF(F24="","",ROUND(40 * (IF(F24=1, 1, 0) - M24),0)) -> 22 | O24: =IF(F24="","",ROUND(G24 + N24 + IF(F24=1, 3, 0),0)) -> 563 | P24: =IF(F24="","",ROUND(H24 + N24 + IF(F24=1, 3, 0),0)) -> 481 | Q24: =IF(F24="","",ROUND(I24 - N24 + IF(F24=2, 3, 0),0)) -> 473 | R24: =IF(F24="","",ROUND(J24 - N24 + IF(F24=2, 3, 0),0)) -> 555
A25: =IF(B25="","", ROW()-1) -> 24 | B25: Francia | C25: Gae | D25: Vesco | E25: Picci | F25: 1 | G25: =IFERROR(__xludf.DUMMYFUNCTION("IF(B25="""","""",ROUND(XLOOKUP(B25, FLATTEN(B$1:E24), FLATTEN(O$1:R24), 500, 0, -1)))"),555.0) -> 555 | H25: =IFERROR(__xludf.DUMMYFUNCTION("IF(C25="""","""",ROUND(XLOOKUP(C25, FLATTEN(B$1:E24), FLATTEN(O$1:R24), 500, 0, -1)))"),508.0) -> 508 | I25: =IFERROR(__xludf.DUMMYFUNCTION("IF(D25="""","""",ROUND(XLOOKUP(D25, FLATTEN(B$1:E24), FLATTEN(O$1:R24), 500, 0, -1)))"),500.0) -> 500 | J25: =IFERROR(__xludf.DUMMYFUNCTION("IF(E25="""","""",ROUND(XLOOKUP(E25, FLATTEN(B$1:E24), FLATTEN(O$1:R24), 500, 0, -1)))"),500.0) -> 500 | K25: =IF(B25="","",ROUND((G25+H25)/2 - ((MAX(G25,H25)-MIN(G25,H25))^2)/1200,0)) -> 530 | L25: =IF(D25="","",ROUND((I25+J25)/2 - ((MAX(I25,J25)-MIN(I25,J25))^2)/1200,0)) -> 500 | M25: =IF(F25="","",ROUND(1 / (1 + 10^((L25-K25)/400)), 2)) -> 0.54 | N25: =IF(F25="","",ROUND(40 * (IF(F25=1, 1, 0) - M25),0)) -> 18 | O25: =IF(F25="","",ROUND(G25 + N25 + IF(F25=1, 3, 0),0)) -> 576 | P25: =IF(F25="","",ROUND(H25 + N25 + IF(F25=1, 3, 0),0)) -> 529 | Q25: =IF(F25="","",ROUND(I25 - N25 + IF(F25=2, 3, 0),0)) -> 482 | R25: =IF(F25="","",ROUND(J25 - N25 + IF(F25=2, 3, 0),0)) -> 482
A26: =IF(B26="","", ROW()-1) -> 25 | B26: Bonny | C26: Feli | D26: Matos | E26: Paolo | F26: 1 | G26: =IFERROR(__xludf.DUMMYFUNCTION("IF(B26="""","""",ROUND(XLOOKUP(B26, FLATTEN(B$1:E25), FLATTEN(O$1:R25), 500, 0, -1)))"),445.0) -> 445 | H26: =IFERROR(__xludf.DUMMYFUNCTION("IF(C26="""","""",ROUND(XLOOKUP(C26, FLATTEN(B$1:E25), FLATTEN(O$1:R25), 500, 0, -1)))"),500.0) -> 500 | I26: =IFERROR(__xludf.DUMMYFUNCTION("IF(D26="""","""",ROUND(XLOOKUP(D26, FLATTEN(B$1:E25), FLATTEN(O$1:R25), 500, 0, -1)))"),563.0) -> 563 | J26: =IFERROR(__xludf.DUMMYFUNCTION("IF(E26="""","""",ROUND(XLOOKUP(E26, FLATTEN(B$1:E25), FLATTEN(O$1:R25), 500, 0, -1)))"),473.0) -> 473 | K26: =IF(B26="","",ROUND((G26+H26)/2 - ((MAX(G26,H26)-MIN(G26,H26))^2)/1200,0)) -> 470 | L26: =IF(D26="","",ROUND((I26+J26)/2 - ((MAX(I26,J26)-MIN(I26,J26))^2)/1200,0)) -> 511 | M26: =IF(F26="","",ROUND(1 / (1 + 10^((L26-K26)/400)), 2)) -> 0.44 | N26: =IF(F26="","",ROUND(40 * (IF(F26=1, 1, 0) - M26),0)) -> 22 | O26: =IF(F26="","",ROUND(G26 + N26 + IF(F26=1, 3, 0),0)) -> 470 | P26: =IF(F26="","",ROUND(H26 + N26 + IF(F26=1, 3, 0),0)) -> 525 | Q26: =IF(F26="","",ROUND(I26 - N26 + IF(F26=2, 3, 0),0)) -> 541 | R26: =IF(F26="","",ROUND(J26 - N26 + IF(F26=2, 3, 0),0)) -> 451
A27: =IF(B27="","", ROW()-1) -> 26 | B27: Vesco | C27: Picci | D27: Matos | E27: Paolo | F27: 1 | G27: =IFERROR(__xludf.DUMMYFUNCTION("IF(B27="""","""",ROUND(XLOOKUP(B27, FLATTEN(B$1:E26), FLATTEN(O$1:R26), 500, 0, -1)))"),482.0) -> 482 | H27: =IFERROR(__xludf.DUMMYFUNCTION("IF(C27="""","""",ROUND(XLOOKUP(C27, FLATTEN(B$1:E26), FLATTEN(O$1:R26), 500, 0, -1)))"),482.0) -> 482 | I27: =IFERROR(__xludf.DUMMYFUNCTION("IF(D27="""","""",ROUND(XLOOKUP(D27, FLATTEN(B$1:E26), FLATTEN(O$1:R26), 500, 0, -1)))"),541.0) -> 541 | J27: =IFERROR(__xludf.DUMMYFUNCTION("IF(E27="""","""",ROUND(XLOOKUP(E27, FLATTEN(B$1:E26), FLATTEN(O$1:R26), 500, 0, -1)))"),451.0) -> 451 | K27: =IF(B27="","",ROUND((G27+H27)/2 - ((MAX(G27,H27)-MIN(G27,H27))^2)/1200,0)) -> 482 | L27: =IF(D27="","",ROUND((I27+J27)/2 - ((MAX(I27,J27)-MIN(I27,J27))^2)/1200,0)) -> 489 | M27: =IF(F27="","",ROUND(1 / (1 + 10^((L27-K27)/400)), 2)) -> 0.49 | N27: =IF(F27="","",ROUND(40 * (IF(F27=1, 1, 0) - M27),0)) -> 20 | O27: =IF(F27="","",ROUND(G27 + N27 + IF(F27=1, 3, 0),0)) -> 505 | P27: =IF(F27="","",ROUND(H27 + N27 + IF(F27=1, 3, 0),0)) -> 505 | Q27: =IF(F27="","",ROUND(I27 - N27 + IF(F27=2, 3, 0),0)) -> 521 | R27: =IF(F27="","",ROUND(J27 - N27 + IF(F27=2, 3, 0),0)) -> 431
A28: =IF(B28="","", ROW()-1) -> 27 | B28: Francia | C28: Gae | D28: Bonny | E28: Feli | F28: 1 | G28: =IFERROR(__xludf.DUMMYFUNCTION("IF(B28="""","""",ROUND(XLOOKUP(B28, FLATTEN(B$1:E27), FLATTEN(O$1:R27), 500, 0, -1)))"),576.0) -> 576 | H28: =IFERROR(__xludf.DUMMYFUNCTION("IF(C28="""","""",ROUND(XLOOKUP(C28, FLATTEN(B$1:E27), FLATTEN(O$1:R27), 500, 0, -1)))"),529.0) -> 529 | I28: =IFERROR(__xludf.DUMMYFUNCTION("IF(D28="""","""",ROUND(XLOOKUP(D28, FLATTEN(B$1:E27), FLATTEN(O$1:R27), 500, 0, -1)))"),470.0) -> 470 | J28: =IFERROR(__xludf.DUMMYFUNCTION("IF(E28="""","""",ROUND(XLOOKUP(E28, FLATTEN(B$1:E27), FLATTEN(O$1:R27), 500, 0, -1)))"),525.0) -> 525 | K28: =IF(B28="","",ROUND((G28+H28)/2 - ((MAX(G28,H28)-MIN(G28,H28))^2)/1200,0)) -> 551 | L28: =IF(D28="","",ROUND((I28+J28)/2 - ((MAX(I28,J28)-MIN(I28,J28))^2)/1200,0)) -> 495 | M28: =IF(F28="","",ROUND(1 / (1 + 10^((L28-K28)/400)), 2)) -> 0.58 | N28: =IF(F28="","",ROUND(40 * (IF(F28=1, 1, 0) - M28),0)) -> 17 | O28: =IF(F28="","",ROUND(G28 + N28 + IF(F28=1, 3, 0),0)) -> 596 | P28: =IF(F28="","",ROUND(H28 + N28 + IF(F28=1, 3, 0),0)) -> 549 | Q28: =IF(F28="","",ROUND(I28 - N28 + IF(F28=2, 3, 0),0)) -> 453 | R28: =IF(F28="","",ROUND(J28 - N28 + IF(F28=2, 3, 0),0)) -> 508
A29: =IF(B29="","", ROW()-1) -> 28 | B29: Vesco | C29: Picci | D29: Bonny | E29: Feli | F29: 1 | G29: =IFERROR(__xludf.DUMMYFUNCTION("IF(B29="""","""",ROUND(XLOOKUP(B29, FLATTEN(B$1:E28), FLATTEN(O$1:R28), 500, 0, -1)))"),505.0) -> 505 | H29: =IFERROR(__xludf.DUMMYFUNCTION("IF(C29="""","""",ROUND(XLOOKUP(C29, FLATTEN(B$1:E28), FLATTEN(O$1:R28), 500, 0, -1)))"),505.0) -> 505 | I29: =IFERROR(__xludf.DUMMYFUNCTION("IF(D29="""","""",ROUND(XLOOKUP(D29, FLATTEN(B$1:E28), FLATTEN(O$1:R28), 500, 0, -1)))"),453.0) -> 453 | J29: =IFERROR(__xludf.DUMMYFUNCTION("IF(E29="""","""",ROUND(XLOOKUP(E29, FLATTEN(B$1:E28), FLATTEN(O$1:R28), 500, 0, -1)))"),508.0) -> 508 | K29: =IF(B29="","",ROUND((G29+H29)/2 - ((MAX(G29,H29)-MIN(G29,H29))^2)/1200,0)) -> 505 | L29: =IF(D29="","",ROUND((I29+J29)/2 - ((MAX(I29,J29)-MIN(I29,J29))^2)/1200,0)) -> 478 | M29: =IF(F29="","",ROUND(1 / (1 + 10^((L29-K29)/400)), 2)) -> 0.54 | N29: =IF(F29="","",ROUND(40 * (IF(F29=1, 1, 0) - M29),0)) -> 18 | O29: =IF(F29="","",ROUND(G29 + N29 + IF(F29=1, 3, 0),0)) -> 526 | P29: =IF(F29="","",ROUND(H29 + N29 + IF(F29=1, 3, 0),0)) -> 526 | Q29: =IF(F29="","",ROUND(I29 - N29 + IF(F29=2, 3, 0),0)) -> 435 | R29: =IF(F29="","",ROUND(J29 - N29 + IF(F29=2, 3, 0),0)) -> 490
A30: =IF(B30="","", ROW()-1) -> 29 | B30: Francia | C30: Gae | D30: Matos | E30: Paolo | F30: 1 | G30: =IFERROR(__xludf.DUMMYFUNCTION("IF(B30="""","""",ROUND(XLOOKUP(B30, FLATTEN(B$1:E29), FLATTEN(O$1:R29), 500, 0, -1)))"),596.0) -> 596 | H30: =IFERROR(__xludf.DUMMYFUNCTION("IF(C30="""","""",ROUND(XLOOKUP(C30, FLATTEN(B$1:E29), FLATTEN(O$1:R29), 500, 0, -1)))"),549.0) -> 549 | I30: =IFERROR(__xludf.DUMMYFUNCTION("IF(D30="""","""",ROUND(XLOOKUP(D30, FLATTEN(B$1:E29), FLATTEN(O$1:R29), 500, 0, -1)))"),521.0) -> 521 | J30: =IFERROR(__xludf.DUMMYFUNCTION("IF(E30="""","""",ROUND(XLOOKUP(E30, FLATTEN(B$1:E29), FLATTEN(O$1:R29), 500, 0, -1)))"),431.0) -> 431 | K30: =IF(B30="","",ROUND((G30+H30)/2 - ((MAX(G30,H30)-MIN(G30,H30))^2)/1200,0)) -> 571 | L30: =IF(D30="","",ROUND((I30+J30)/2 - ((MAX(I30,J30)-MIN(I30,J30))^2)/1200,0)) -> 469 | M30: =IF(F30="","",ROUND(1 / (1 + 10^((L30-K30)/400)), 2)) -> 0.64 | N30: =IF(F30="","",ROUND(40 * (IF(F30=1, 1, 0) - M30),0)) -> 14 | O30: =IF(F30="","",ROUND(G30 + N30 + IF(F30=1, 3, 0),0)) -> 613 | P30: =IF(F30="","",ROUND(H30 + N30 + IF(F30=1, 3, 0),0)) -> 566 | Q30: =IF(F30="","",ROUND(I30 - N30 + IF(F30=2, 3, 0),0)) -> 507 | R30: =IF(F30="","",ROUND(J30 - N30 + IF(F30=2, 3, 0),0)) -> 417
A31: =IF(B31="","", ROW()-1) -> 30 | B31: Francia | C31: Gae | D31: Vesco | E31: Picci | F31: 1 | G31: =IFERROR(__xludf.DUMMYFUNCTION("IF(B31="""","""",ROUND(XLOOKUP(B31, FLATTEN(B$1:E30), FLATTEN(O$1:R30), 500, 0, -1)))"),613.0) -> 613 | H31: =IFERROR(__xludf.DUMMYFUNCTION("IF(C31="""","""",ROUND(XLOOKUP(C31, FLATTEN(B$1:E30), FLATTEN(O$1:R30), 500, 0, -1)))"),566.0) -> 566 | I31: =IFERROR(__xludf.DUMMYFUNCTION("IF(D31="""","""",ROUND(XLOOKUP(D31, FLATTEN(B$1:E30), FLATTEN(O$1:R30), 500, 0, -1)))"),526.0) -> 526 | J31: =IFERROR(__xludf.DUMMYFUNCTION("IF(E31="""","""",ROUND(XLOOKUP(E31, FLATTEN(B$1:E30), FLATTEN(O$1:R30), 500, 0, -1)))"),526.0) -> 526 | K31: =IF(B31="","",ROUND((G31+H31)/2 - ((MAX(G31,H31)-MIN(G31,H31))^2)/1200,0)) -> 588 | L31: =IF(D31="","",ROUND((I31+J31)/2 - ((MAX(I31,J31)-MIN(I31,J31))^2)/1200,0)) -> 526 | M31: =IF(F31="","",ROUND(1 / (1 + 10^((L31-K31)/400)), 2)) -> 0.59 | N31: =IF(F31="","",ROUND(40 * (IF(F31=1, 1, 0) - M31),0)) -> 16 | O31: =IF(F31="","",ROUND(G31 + N31 + IF(F31=1, 3, 0),0)) -> 632 | P31: =IF(F31="","",ROUND(H31 + N31 + IF(F31=1, 3, 0),0)) -> 585 | Q31: =IF(F31="","",ROUND(I31 - N31 + IF(F31=2, 3, 0),0)) -> 510 | R31: =IF(F31="","",ROUND(J31 - N31 + IF(F31=2, 3, 0),0)) -> 510
A32: =IF(B32="","", ROW()-1) -> 31 | B32: Matos | C32: Paolo | D32: Bonny | E32: Feli | F32: 1 | G32: =IFERROR(__xludf.DUMMYFUNCTION("IF(B32="""","""",ROUND(XLOOKUP(B32, FLATTEN(B$1:E31), FLATTEN(O$1:R31), 500, 0, -1)))"),507.0) -> 507 | H32: =IFERROR(__xludf.DUMMYFUNCTION("IF(C32="""","""",ROUND(XLOOKUP(C32, FLATTEN(B$1:E31), FLATTEN(O$1:R31), 500, 0, -1)))"),417.0) -> 417 | I32: =IFERROR(__xludf.DUMMYFUNCTION("IF(D32="""","""",ROUND(XLOOKUP(D32, FLATTEN(B$1:E31), FLATTEN(O$1:R31), 500, 0, -1)))"),435.0) -> 435 | J32: =IFERROR(__xludf.DUMMYFUNCTION("IF(E32="""","""",ROUND(XLOOKUP(E32, FLATTEN(B$1:E31), FLATTEN(O$1:R31), 500, 0, -1)))"),490.0) -> 490 | K32: =IF(B32="","",ROUND((G32+H32)/2 - ((MAX(G32,H32)-MIN(G32,H32))^2)/1200,0)) -> 455 | L32: =IF(D32="","",ROUND((I32+J32)/2 - ((MAX(I32,J32)-MIN(I32,J32))^2)/1200,0)) -> 460 | M32: =IF(F32="","",ROUND(1 / (1 + 10^((L32-K32)/400)), 2)) -> 0.49 | N32: =IF(F32="","",ROUND(40 * (IF(F32=1, 1, 0) - M32),0)) -> 20 | O32: =IF(F32="","",ROUND(G32 + N32 + IF(F32=1, 3, 0),0)) -> 530 | P32: =IF(F32="","",ROUND(H32 + N32 + IF(F32=1, 3, 0),0)) -> 440 | Q32: =IF(F32="","",ROUND(I32 - N32 + IF(F32=2, 3, 0),0)) -> 415 | R32: =IF(F32="","",ROUND(J32 - N32 + IF(F32=2, 3, 0),0)) -> 470
A33: =IF(B33="","", ROW()-1) -> 32 | B33: Vesco | C33: Picci | D33: Matos | E33: Paolo | F33: 1 | G33: =IFERROR(__xludf.DUMMYFUNCTION("IF(B33="""","""",ROUND(XLOOKUP(B33, FLATTEN(B$1:E32), FLATTEN(O$1:R32), 500, 0, -1)))"),510.0) -> 510 | H33: =IFERROR(__xludf.DUMMYFUNCTION("IF(C33="""","""",ROUND(XLOOKUP(C33, FLATTEN(B$1:E32), FLATTEN(O$1:R32), 500, 0, -1)))"),510.0) -> 510 | I33: =IFERROR(__xludf.DUMMYFUNCTION("IF(D33="""","""",ROUND(XLOOKUP(D33, FLATTEN(B$1:E32), FLATTEN(O$1:R32), 500, 0, -1)))"),530.0) -> 530 | J33: =IFERROR(__xludf.DUMMYFUNCTION("IF(E33="""","""",ROUND(XLOOKUP(E33, FLATTEN(B$1:E32), FLATTEN(O$1:R32), 500, 0, -1)))"),440.0) -> 440 | K33: =IF(B33="","",ROUND((G33+H33)/2 - ((MAX(G33,H33)-MIN(G33,H33))^2)/1200,0)) -> 510 | L33: =IF(D33="","",ROUND((I33+J33)/2 - ((MAX(I33,J33)-MIN(I33,J33))^2)/1200,0)) -> 478 | M33: =IF(F33="","",ROUND(1 / (1 + 10^((L33-K33)/400)), 2)) -> 0.55 | N33: =IF(F33="","",ROUND(40 * (IF(F33=1, 1, 0) - M33),0)) -> 18 | O33: =IF(F33="","",ROUND(G33 + N33 + IF(F33=1, 3, 0),0)) -> 531 | P33: =IF(F33="","",ROUND(H33 + N33 + IF(F33=1, 3, 0),0)) -> 531 | Q33: =IF(F33="","",ROUND(I33 - N33 + IF(F33=2, 3, 0),0)) -> 512 | R33: =IF(F33="","",ROUND(J33 - N33 + IF(F33=2, 3, 0),0)) -> 422
A34: =IF(B34="","", ROW()-1) -> 33 | B34: Francia | C34: Gae | D34: Bonny | E34: Feli | F34: 1 | G34: =IFERROR(__xludf.DUMMYFUNCTION("IF(B34="""","""",ROUND(XLOOKUP(B34, FLATTEN(B$1:E33), FLATTEN(O$1:R33), 500, 0, -1)))"),632.0) -> 632 | H34: =IFERROR(__xludf.DUMMYFUNCTION("IF(C34="""","""",ROUND(XLOOKUP(C34, FLATTEN(B$1:E33), FLATTEN(O$1:R33), 500, 0, -1)))"),585.0) -> 585 | I34: =IFERROR(__xludf.DUMMYFUNCTION("IF(D34="""","""",ROUND(XLOOKUP(D34, FLATTEN(B$1:E33), FLATTEN(O$1:R33), 500, 0, -1)))"),415.0) -> 415 | J34: =IFERROR(__xludf.DUMMYFUNCTION("IF(E34="""","""",ROUND(XLOOKUP(E34, FLATTEN(B$1:E33), FLATTEN(O$1:R33), 500, 0, -1)))"),470.0) -> 470 | K34: =IF(B34="","",ROUND((G34+H34)/2 - ((MAX(G34,H34)-MIN(G34,H34))^2)/1200,0)) -> 607 | L34: =IF(D34="","",ROUND((I34+J34)/2 - ((MAX(I34,J34)-MIN(I34,J34))^2)/1200,0)) -> 440 | M34: =IF(F34="","",ROUND(1 / (1 + 10^((L34-K34)/400)), 2)) -> 0.72 | N34: =IF(F34="","",ROUND(40 * (IF(F34=1, 1, 0) - M34),0)) -> 11 | O34: =IF(F34="","",ROUND(G34 + N34 + IF(F34=1, 3, 0),0)) -> 646 | P34: =IF(F34="","",ROUND(H34 + N34 + IF(F34=1, 3, 0),0)) -> 599 | Q34: =IF(F34="","",ROUND(I34 - N34 + IF(F34=2, 3, 0),0)) -> 404 | R34: =IF(F34="","",ROUND(J34 - N34 + IF(F34=2, 3, 0),0)) -> 459
A35: =IF(B35="","", ROW()-1) -> 34 | B35: Bonny | C35: Bonny | D35: Vesco | E35: Picci | F35: 1 | G35: =IFERROR(__xludf.DUMMYFUNCTION("IF(B35="""","""",ROUND(XLOOKUP(B35, FLATTEN(B$1:E34), FLATTEN(O$1:R34), 500, 0, -1)))"),404.0) -> 404 | H35: =IFERROR(__xludf.DUMMYFUNCTION("IF(C35="""","""",ROUND(XLOOKUP(C35, FLATTEN(B$1:E34), FLATTEN(O$1:R34), 500, 0, -1)))"),404.0) -> 404 | I35: =IFERROR(__xludf.DUMMYFUNCTION("IF(D35="""","""",ROUND(XLOOKUP(D35, FLATTEN(B$1:E34), FLATTEN(O$1:R34), 500, 0, -1)))"),531.0) -> 531 | J35: =IFERROR(__xludf.DUMMYFUNCTION("IF(E35="""","""",ROUND(XLOOKUP(E35, FLATTEN(B$1:E34), FLATTEN(O$1:R34), 500, 0, -1)))"),531.0) -> 531 | K35: =IF(B35="","",ROUND((G35+H35)/2 - ((MAX(G35,H35)-MIN(G35,H35))^2)/1200,0)) -> 404 | L35: =IF(D35="","",ROUND((I35+J35)/2 - ((MAX(I35,J35)-MIN(I35,J35))^2)/1200,0)) -> 531 | M35: =IF(F35="","",ROUND(1 / (1 + 10^((L35-K35)/400)), 2)) -> 0.32 | N35: =IF(F35="","",ROUND(40 * (IF(F35=1, 1, 0) - M35),0)) -> 27 | O35: =IF(F35="","",ROUND(G35 + N35 + IF(F35=1, 3, 0),0)) -> 434 | P35: =IF(F35="","",ROUND(H35 + N35 + IF(F35=1, 3, 0),0)) -> 434 | Q35: =IF(F35="","",ROUND(I35 - N35 + IF(F35=2, 3, 0),0)) -> 504 | R35: =IF(F35="","",ROUND(J35 - N35 + IF(F35=2, 3, 0),0)) -> 504
A36: =IF(B36="","", ROW()-1) -> 35 | B36: Matos | C36: Paolo | D36: Francia | E36: Gae | F36: 1 | G36: =IFERROR(__xludf.DUMMYFUNCTION("IF(B36="""","""",ROUND(XLOOKUP(B36, FLATTEN(B$1:E35), FLATTEN(O$1:R35), 500, 0, -1)))"),512.0) -> 512 | H36: =IFERROR(__xludf.DUMMYFUNCTION("IF(C36="""","""",ROUND(XLOOKUP(C36, FLATTEN(B$1:E35), FLATTEN(O$1:R35), 500, 0, -1)))"),422.0) -> 422 | I36: =IFERROR(__xludf.DUMMYFUNCTION("IF(D36="""","""",ROUND(XLOOKUP(D36, FLATTEN(B$1:E35), FLATTEN(O$1:R35), 500, 0, -1)))"),646.0) -> 646 | J36: =IFERROR(__xludf.DUMMYFUNCTION("IF(E36="""","""",ROUND(XLOOKUP(E36, FLATTEN(B$1:E35), FLATTEN(O$1:R35), 500, 0, -1)))"),599.0) -> 599 | K36: =IF(B36="","",ROUND((G36+H36)/2 - ((MAX(G36,H36)-MIN(G36,H36))^2)/1200,0)) -> 460 | L36: =IF(D36="","",ROUND((I36+J36)/2 - ((MAX(I36,J36)-MIN(I36,J36))^2)/1200,0)) -> 621 | M36: =IF(F36="","",ROUND(1 / (1 + 10^((L36-K36)/400)), 2)) -> 0.28 | N36: =IF(F36="","",ROUND(40 * (IF(F36=1, 1, 0) - M36),0)) -> 29 | O36: =IF(F36="","",ROUND(G36 + N36 + IF(F36=1, 3, 0),0)) -> 544 | P36: =IF(F36="","",ROUND(H36 + N36 + IF(F36=1, 3, 0),0)) -> 454 | Q36: =IF(F36="","",ROUND(I36 - N36 + IF(F36=2, 3, 0),0)) -> 617 | R36: =IF(F36="","",ROUND(J36 - N36 + IF(F36=2, 3, 0),0)) -> 570
A37: =IF(B37="","", ROW()-1) -> 36 | B37: Filli | C37: Filli | D37: Matos | E37: Gae | F37: 1 | G37: =IFERROR(__xludf.DUMMYFUNCTION("IF(B37="""","""",ROUND(XLOOKUP(B37, FLATTEN(B$1:E36), FLATTEN(O$1:R36), 500, 0, -1)))"),481.0) -> 481 | H37: =IFERROR(__xludf.DUMMYFUNCTION("IF(C37="""","""",ROUND(XLOOKUP(C37, FLATTEN(B$1:E36), FLATTEN(O$1:R36), 500, 0, -1)))"),481.0) -> 481 | I37: =IFERROR(__xludf.DUMMYFUNCTION("IF(D37="""","""",ROUND(XLOOKUP(D37, FLATTEN(B$1:E36), FLATTEN(O$1:R36), 500, 0, -1)))"),544.0) -> 544 | J37: =IFERROR(__xludf.DUMMYFUNCTION("IF(E37="""","""",ROUND(XLOOKUP(E37, FLATTEN(B$1:E36), FLATTEN(O$1:R36), 500, 0, -1)))"),570.0) -> 570 | K37: =IF(B37="","",ROUND((G37+H37)/2 - ((MAX(G37,H37)-MIN(G37,H37))^2)/1200,0)) -> 481 | L37: =IF(D37="","",ROUND((I37+J37)/2 - ((MAX(I37,J37)-MIN(I37,J37))^2)/1200,0)) -> 556 | M37: =IF(F37="","",ROUND(1 / (1 + 10^((L37-K37)/400)), 2)) -> 0.39 | N37: =IF(F37="","",ROUND(40 * (IF(F37=1, 1, 0) - M37),0)) -> 24 | O37: =IF(F37="","",ROUND(G37 + N37 + IF(F37=1, 3, 0),0)) -> 508 | P37: =IF(F37="","",ROUND(H37 + N37 + IF(F37=1, 3, 0),0)) -> 508 | Q37: =IF(F37="","",ROUND(I37 - N37 + IF(F37=2, 3, 0),0)) -> 520 | R37: =IF(F37="","",ROUND(J37 - N37 + IF(F37=2, 3, 0),0)) -> 546
A38: =IF(B38="","", ROW()-1) -> 37 | B38: Vesco | C38: Bonny | D38: Filli | E38: Paolo | F38: 1 | G38: =IFERROR(__xludf.DUMMYFUNCTION("IF(B38="""","""",ROUND(XLOOKUP(B38, FLATTEN(B$1:E37), FLATTEN(O$1:R37), 500, 0, -1)))"),504.0) -> 504 | H38: =IFERROR(__xludf.DUMMYFUNCTION("IF(C38="""","""",ROUND(XLOOKUP(C38, FLATTEN(B$1:E37), FLATTEN(O$1:R37), 500, 0, -1)))"),434.0) -> 434 | I38: =IFERROR(__xludf.DUMMYFUNCTION("IF(D38="""","""",ROUND(XLOOKUP(D38, FLATTEN(B$1:E37), FLATTEN(O$1:R37), 500, 0, -1)))"),508.0) -> 508 | J38: =IFERROR(__xludf.DUMMYFUNCTION("IF(E38="""","""",ROUND(XLOOKUP(E38, FLATTEN(B$1:E37), FLATTEN(O$1:R37), 500, 0, -1)))"),454.0) -> 454 | K38: =IF(B38="","",ROUND((G38+H38)/2 - ((MAX(G38,H38)-MIN(G38,H38))^2)/1200,0)) -> 465 | L38: =IF(D38="","",ROUND((I38+J38)/2 - ((MAX(I38,J38)-MIN(I38,J38))^2)/1200,0)) -> 479 | M38: =IF(F38="","",ROUND(1 / (1 + 10^((L38-K38)/400)), 2)) -> 0.48 | N38: =IF(F38="","",ROUND(40 * (IF(F38=1, 1, 0) - M38),0)) -> 21 | O38: =IF(F38="","",ROUND(G38 + N38 + IF(F38=1, 3, 0),0)) -> 528 | P38: =IF(F38="","",ROUND(H38 + N38 + IF(F38=1, 3, 0),0)) -> 458 | Q38: =IF(F38="","",ROUND(I38 - N38 + IF(F38=2, 3, 0),0)) -> 487 | R38: =IF(F38="","",ROUND(J38 - N38 + IF(F38=2, 3, 0),0)) -> 433
